2018-02-10 15:17:08,940 CRITICAL uncaught exception:

Traceback (most recent call last):
  File "D:\00 eigene Daten\000 FH\S 4\Regelungstechnik\Regelungsversuch\microRay\gui\plotWidget.py", line 300, in updatePlots
    self.updateValueLabels()
  File "D:\00 eigene Daten\000 FH\S 4\Regelungstechnik\Regelungsversuch\microRay\gui\plotWidget.py", line 379, in updateValueLabels
    self.refreshTimeLabels(relativeTime, relativeTimeOne)
  File "D:\00 eigene Daten\000 FH\S 4\Regelungstechnik\Regelungsversuch\microRay\gui\plotWidget.py", line 269, in refreshTimeLabels
    self.time0Label.setText(u"t0 {.3f} s".format(time0))
AttributeError: 'float' object has no attribute '3f'

2018-02-10 15:17:08,943 ERROR    uncaught exception
2018-02-10 15:17:08,973 ERROR    
2018-02-10 15:17:09,017 CRITICAL uncaught exception:

Traceback (most recent call last):
  File "D:\00 eigene Daten\000 FH\S 4\Regelungstechnik\Regelungsversuch\microRay\gui\plotWidget.py", line 300, in updatePlots
    self.updateValueLabels()
  File "D:\00 eigene Daten\000 FH\S 4\Regelungstechnik\Regelungsversuch\microRay\gui\plotWidget.py", line 379, in updateValueLabels
    self.refreshTimeLabels(relativeTime, relativeTimeOne)
  File "D:\00 eigene Daten\000 FH\S 4\Regelungstechnik\Regelungsversuch\microRay\gui\plotWidget.py", line 269, in refreshTimeLabels
    self.time0Label.setText(u"t0 {.3f} s".format(time0))
AttributeError: 'float' object has no attribute '3f'

2018-02-10 15:17:09,019 ERROR    uncaught exception
2018-02-10 15:17:09,019 ERROR    
2018-02-10 15:17:09,039 CRITICAL uncaught exception:

Traceback (most recent call last):
  File "D:\00 eigene Daten\000 FH\S 4\Regelungstechnik\Regelungsversuch\microRay\gui\plotWidget.py", line 300, in updatePlots
    self.updateValueLabels()
  File "D:\00 eigene Daten\000 FH\S 4\Regelungstechnik\Regelungsversuch\microRay\gui\plotWidget.py", line 379, in updateValueLabels
    self.refreshTimeLabels(relativeTime, relativeTimeOne)
  File "D:\00 eigene Daten\000 FH\S 4\Regelungstechnik\Regelungsversuch\microRay\gui\plotWidget.py", line 269, in refreshTimeLabels
    self.time0Label.setText(u"t0 {.3f} s".format(time0))
AttributeError: 'float' object has no attribute '3f'

2018-02-10 15:17:09,040 ERROR    uncaught exception
2018-02-10 15:17:09,040 ERROR    
2018-02-10 15:17:09,078 CRITICAL uncaught exception:

Traceback (most recent call last):
  File "D:\00 eigene Daten\000 FH\S 4\Regelungstechnik\Regelungsversuch\microRay\gui\plotWidget.py", line 300, in updatePlots
    self.updateValueLabels()
  File "D:\00 eigene Daten\000 FH\S 4\Regelungstechnik\Regelungsversuch\microRay\gui\plotWidget.py", line 379, in updateValueLabels
    self.refreshTimeLabels(relativeTime, relativeTimeOne)
  File "D:\00 eigene Daten\000 FH\S 4\Regelungstechnik\Regelungsversuch\microRay\gui\plotWidget.py", line 269, in refreshTimeLabels
    self.time0Label.setText(u"t0 {.3f} s".format(time0))
AttributeError: 'float' object has no attribute '3f'

2018-02-10 15:17:09,081 ERROR    uncaught exception
2018-02-10 15:17:09,081 ERROR    
2018-02-10 15:17:09,131 CRITICAL uncaught exception:

Traceback (most recent call last):
  File "D:\00 eigene Daten\000 FH\S 4\Regelungstechnik\Regelungsversuch\microRay\gui\plotWidget.py", line 300, in updatePlots
    self.updateValueLabels()
  File "D:\00 eigene Daten\000 FH\S 4\Regelungstechnik\Regelungsversuch\microRay\gui\plotWidget.py", line 379, in updateValueLabels
    self.refreshTimeLabels(relativeTime, relativeTimeOne)
  File "D:\00 eigene Daten\000 FH\S 4\Regelungstechnik\Regelungsversuch\microRay\gui\plotWidget.py", line 269, in refreshTimeLabels
    self.time0Label.setText(u"t0 {.3f} s".format(time0))
AttributeError: 'float' object has no attribute '3f'

2018-02-10 15:17:09,132 ERROR    uncaught exception
2018-02-10 15:17:09,132 ERROR    
2018-02-10 15:17:09,180 CRITICAL uncaught exception:

Traceback (most recent call last):
  File "D:\00 eigene Daten\000 FH\S 4\Regelungstechnik\Regelungsversuch\microRay\gui\plotWidget.py", line 300, in updatePlots
    self.updateValueLabels()
  File "D:\00 eigene Daten\000 FH\S 4\Regelungstechnik\Regelungsversuch\microRay\gui\plotWidget.py", line 379, in updateValueLabels
    self.refreshTimeLabels(relativeTime, relativeTimeOne)
  File "D:\00 eigene Daten\000 FH\S 4\Regelungstechnik\Regelungsversuch\microRay\gui\plotWidget.py", line 269, in refreshTimeLabels
    self.time0Label.setText(u"t0 {.3f} s".format(time0))
AttributeError: 'float' object has no attribute '3f'

2018-02-10 15:17:09,180 ERROR    uncaught exception
2018-02-10 15:17:09,180 ERROR    
2018-02-10 15:17:09,223 CRITICAL uncaught exception:

Traceback (most recent call last):
  File "D:\00 eigene Daten\000 FH\S 4\Regelungstechnik\Regelungsversuch\microRay\gui\plotWidget.py", line 300, in updatePlots
    self.updateValueLabels()
  File "D:\00 eigene Daten\000 FH\S 4\Regelungstechnik\Regelungsversuch\microRay\gui\plotWidget.py", line 379, in updateValueLabels
    self.refreshTimeLabels(relativeTime, relativeTimeOne)
  File "D:\00 eigene Daten\000 FH\S 4\Regelungstechnik\Regelungsversuch\microRay\gui\plotWidget.py", line 269, in refreshTimeLabels
    self.time0Label.setText(u"t0 {.3f} s".format(time0))
AttributeError: 'float' object has no attribute '3f'

2018-02-10 15:17:09,226 ERROR    uncaught exception
2018-02-10 15:17:09,226 ERROR    
2018-02-10 15:17:09,267 CRITICAL uncaught exception:

Traceback (most recent call last):
  File "D:\00 eigene Daten\000 FH\S 4\Regelungstechnik\Regelungsversuch\microRay\gui\plotWidget.py", line 300, in updatePlots
    self.updateValueLabels()
  File "D:\00 eigene Daten\000 FH\S 4\Regelungstechnik\Regelungsversuch\microRay\gui\plotWidget.py", line 379, in updateValueLabels
    self.refreshTimeLabels(relativeTime, relativeTimeOne)
  File "D:\00 eigene Daten\000 FH\S 4\Regelungstechnik\Regelungsversuch\microRay\gui\plotWidget.py", line 269, in refreshTimeLabels
    self.time0Label.setText(u"t0 {.3f} s".format(time0))
AttributeError: 'float' object has no attribute '3f'

2018-02-10 15:17:09,269 ERROR    uncaught exception
2018-02-10 15:17:09,269 ERROR    
2018-02-10 15:17:09,315 CRITICAL uncaught exception:

Traceback (most recent call last):
  File "D:\00 eigene Daten\000 FH\S 4\Regelungstechnik\Regelungsversuch\microRay\gui\plotWidget.py", line 300, in updatePlots
    self.updateValueLabels()
  File "D:\00 eigene Daten\000 FH\S 4\Regelungstechnik\Regelungsversuch\microRay\gui\plotWidget.py", line 379, in updateValueLabels
    self.refreshTimeLabels(relativeTime, relativeTimeOne)
  File "D:\00 eigene Daten\000 FH\S 4\Regelungstechnik\Regelungsversuch\microRay\gui\plotWidget.py", line 269, in refreshTimeLabels
    self.time0Label.setText(u"t0 {.3f} s".format(time0))
AttributeError: 'float' object has no attribute '3f'

2018-02-10 15:17:09,315 ERROR    uncaught exception
2018-02-10 15:17:09,316 ERROR    
2018-02-10 15:17:09,364 CRITICAL uncaught exception:

Traceback (most recent call last):
  File "D:\00 eigene Daten\000 FH\S 4\Regelungstechnik\Regelungsversuch\microRay\gui\plotWidget.py", line 300, in updatePlots
    self.updateValueLabels()
  File "D:\00 eigene Daten\000 FH\S 4\Regelungstechnik\Regelungsversuch\microRay\gui\plotWidget.py", line 379, in updateValueLabels
    self.refreshTimeLabels(relativeTime, relativeTimeOne)
  File "D:\00 eigene Daten\000 FH\S 4\Regelungstechnik\Regelungsversuch\microRay\gui\plotWidget.py", line 269, in refreshTimeLabels
    self.time0Label.setText(u"t0 {.3f} s".format(time0))
AttributeError: 'float' object has no attribute '3f'

2018-02-10 15:17:09,365 ERROR    uncaught exception
2018-02-10 15:17:09,365 ERROR    
2018-02-10 15:17:09,411 CRITICAL uncaught exception:

Traceback (most recent call last):
  File "D:\00 eigene Daten\000 FH\S 4\Regelungstechnik\Regelungsversuch\microRay\gui\plotWidget.py", line 300, in updatePlots
    self.updateValueLabels()
  File "D:\00 eigene Daten\000 FH\S 4\Regelungstechnik\Regelungsversuch\microRay\gui\plotWidget.py", line 379, in updateValueLabels
    self.refreshTimeLabels(relativeTime, relativeTimeOne)
  File "D:\00 eigene Daten\000 FH\S 4\Regelungstechnik\Regelungsversuch\microRay\gui\plotWidget.py", line 269, in refreshTimeLabels
    self.time0Label.setText(u"t0 {.3f} s".format(time0))
AttributeError: 'float' object has no attribute '3f'

2018-02-10 15:17:09,413 ERROR    uncaught exception
2018-02-10 15:17:09,413 ERROR    
2018-02-10 15:17:09,464 CRITICAL uncaught exception:

Traceback (most recent call last):
  File "D:\00 eigene Daten\000 FH\S 4\Regelungstechnik\Regelungsversuch\microRay\gui\plotWidget.py", line 300, in updatePlots
    self.updateValueLabels()
  File "D:\00 eigene Daten\000 FH\S 4\Regelungstechnik\Regelungsversuch\microRay\gui\plotWidget.py", line 379, in updateValueLabels
    self.refreshTimeLabels(relativeTime, relativeTimeOne)
  File "D:\00 eigene Daten\000 FH\S 4\Regelungstechnik\Regelungsversuch\microRay\gui\plotWidget.py", line 269, in refreshTimeLabels
    self.time0Label.setText(u"t0 {.3f} s".format(time0))
AttributeError: 'float' object has no attribute '3f'

2018-02-10 15:17:09,470 ERROR    uncaught exception
2018-02-10 15:17:09,470 ERROR    
2018-02-10 15:17:09,548 CRITICAL uncaught exception:

Traceback (most recent call last):
  File "D:\00 eigene Daten\000 FH\S 4\Regelungstechnik\Regelungsversuch\microRay\gui\plotWidget.py", line 300, in updatePlots
    self.updateValueLabels()
  File "D:\00 eigene Daten\000 FH\S 4\Regelungstechnik\Regelungsversuch\microRay\gui\plotWidget.py", line 379, in updateValueLabels
    self.refreshTimeLabels(relativeTime, relativeTimeOne)
  File "D:\00 eigene Daten\000 FH\S 4\Regelungstechnik\Regelungsversuch\microRay\gui\plotWidget.py", line 269, in refreshTimeLabels
    self.time0Label.setText(u"t0 {.3f} s".format(time0))
AttributeError: 'float' object has no attribute '3f'

2018-02-10 15:17:09,552 ERROR    uncaught exception
2018-02-10 15:17:09,552 ERROR    
2018-02-10 15:17:09,596 CRITICAL uncaught exception:

Traceback (most recent call last):
  File "D:\00 eigene Daten\000 FH\S 4\Regelungstechnik\Regelungsversuch\microRay\gui\plotWidget.py", line 300, in updatePlots
    self.updateValueLabels()
  File "D:\00 eigene Daten\000 FH\S 4\Regelungstechnik\Regelungsversuch\microRay\gui\plotWidget.py", line 379, in updateValueLabels
    self.refreshTimeLabels(relativeTime, relativeTimeOne)
  File "D:\00 eigene Daten\000 FH\S 4\Regelungstechnik\Regelungsversuch\microRay\gui\plotWidget.py", line 269, in refreshTimeLabels
    self.time0Label.setText(u"t0 {.3f} s".format(time0))
AttributeError: 'float' object has no attribute '3f'

2018-02-10 15:17:09,598 ERROR    uncaught exception
2018-02-10 15:17:09,598 ERROR    
2018-02-10 15:17:09,644 CRITICAL uncaught exception:

Traceback (most recent call last):
  File "D:\00 eigene Daten\000 FH\S 4\Regelungstechnik\Regelungsversuch\microRay\gui\plotWidget.py", line 300, in updatePlots
    self.updateValueLabels()
  File "D:\00 eigene Daten\000 FH\S 4\Regelungstechnik\Regelungsversuch\microRay\gui\plotWidget.py", line 379, in updateValueLabels
    self.refreshTimeLabels(relativeTime, relativeTimeOne)
  File "D:\00 eigene Daten\000 FH\S 4\Regelungstechnik\Regelungsversuch\microRay\gui\plotWidget.py", line 269, in refreshTimeLabels
    self.time0Label.setText(u"t0 {.3f} s".format(time0))
AttributeError: 'float' object has no attribute '3f'

2018-02-10 15:17:09,645 ERROR    uncaught exception
2018-02-10 15:17:09,645 ERROR    
2018-02-10 15:17:09,690 CRITICAL uncaught exception:

Traceback (most recent call last):
  File "D:\00 eigene Daten\000 FH\S 4\Regelungstechnik\Regelungsversuch\microRay\gui\plotWidget.py", line 300, in updatePlots
    self.updateValueLabels()
  File "D:\00 eigene Daten\000 FH\S 4\Regelungstechnik\Regelungsversuch\microRay\gui\plotWidget.py", line 379, in updateValueLabels
    self.refreshTimeLabels(relativeTime, relativeTimeOne)
  File "D:\00 eigene Daten\000 FH\S 4\Regelungstechnik\Regelungsversuch\microRay\gui\plotWidget.py", line 269, in refreshTimeLabels
    self.time0Label.setText(u"t0 {.3f} s".format(time0))
AttributeError: 'float' object has no attribute '3f'

2018-02-10 15:17:09,693 ERROR    uncaught exception
2018-02-10 15:17:09,693 ERROR    
2018-02-10 15:17:09,739 CRITICAL uncaught exception:

Traceback (most recent call last):
  File "D:\00 eigene Daten\000 FH\S 4\Regelungstechnik\Regelungsversuch\microRay\gui\plotWidget.py", line 300, in updatePlots
    self.updateValueLabels()
  File "D:\00 eigene Daten\000 FH\S 4\Regelungstechnik\Regelungsversuch\microRay\gui\plotWidget.py", line 379, in updateValueLabels
    self.refreshTimeLabels(relativeTime, relativeTimeOne)
  File "D:\00 eigene Daten\000 FH\S 4\Regelungstechnik\Regelungsversuch\microRay\gui\plotWidget.py", line 269, in refreshTimeLabels
    self.time0Label.setText(u"t0 {.3f} s".format(time0))
AttributeError: 'float' object has no attribute '3f'

2018-02-10 15:17:09,740 ERROR    uncaught exception
2018-02-10 15:17:09,740 ERROR    
2018-02-10 15:17:09,780 CRITICAL uncaught exception:

Traceback (most recent call last):
  File "D:\00 eigene Daten\000 FH\S 4\Regelungstechnik\Regelungsversuch\microRay\gui\plotWidget.py", line 300, in updatePlots
    self.updateValueLabels()
  File "D:\00 eigene Daten\000 FH\S 4\Regelungstechnik\Regelungsversuch\microRay\gui\plotWidget.py", line 379, in updateValueLabels
    self.refreshTimeLabels(relativeTime, relativeTimeOne)
  File "D:\00 eigene Daten\000 FH\S 4\Regelungstechnik\Regelungsversuch\microRay\gui\plotWidget.py", line 269, in refreshTimeLabels
    self.time0Label.setText(u"t0 {.3f} s".format(time0))
AttributeError: 'float' object has no attribute '3f'

2018-02-10 15:17:09,782 ERROR    uncaught exception
2018-02-10 15:17:09,782 ERROR    
2018-02-10 15:17:09,834 CRITICAL uncaught exception:

Traceback (most recent call last):
  File "D:\00 eigene Daten\000 FH\S 4\Regelungstechnik\Regelungsversuch\microRay\gui\plotWidget.py", line 300, in updatePlots
    self.updateValueLabels()
  File "D:\00 eigene Daten\000 FH\S 4\Regelungstechnik\Regelungsversuch\microRay\gui\plotWidget.py", line 379, in updateValueLabels
    self.refreshTimeLabels(relativeTime, relativeTimeOne)
  File "D:\00 eigene Daten\000 FH\S 4\Regelungstechnik\Regelungsversuch\microRay\gui\plotWidget.py", line 269, in refreshTimeLabels
    self.time0Label.setText(u"t0 {.3f} s".format(time0))
AttributeError: 'float' object has no attribute '3f'

2018-02-10 15:17:09,835 ERROR    uncaught exception
2018-02-10 15:17:09,835 ERROR    
2018-02-10 15:17:09,884 CRITICAL uncaught exception:

Traceback (most recent call last):
  File "D:\00 eigene Daten\000 FH\S 4\Regelungstechnik\Regelungsversuch\microRay\gui\plotWidget.py", line 300, in updatePlots
    self.updateValueLabels()
  File "D:\00 eigene Daten\000 FH\S 4\Regelungstechnik\Regelungsversuch\microRay\gui\plotWidget.py", line 379, in updateValueLabels
    self.refreshTimeLabels(relativeTime, relativeTimeOne)
  File "D:\00 eigene Daten\000 FH\S 4\Regelungstechnik\Regelungsversuch\microRay\gui\plotWidget.py", line 269, in refreshTimeLabels
    self.time0Label.setText(u"t0 {.3f} s".format(time0))
AttributeError: 'float' object has no attribute '3f'

2018-02-10 15:17:09,890 ERROR    uncaught exception
2018-02-10 15:17:09,891 ERROR    
2018-02-10 15:17:09,944 CRITICAL uncaught exception:

Traceback (most recent call last):
  File "D:\00 eigene Daten\000 FH\S 4\Regelungstechnik\Regelungsversuch\microRay\gui\plotWidget.py", line 300, in updatePlots
    self.updateValueLabels()
  File "D:\00 eigene Daten\000 FH\S 4\Regelungstechnik\Regelungsversuch\microRay\gui\plotWidget.py", line 379, in updateValueLabels
    self.refreshTimeLabels(relativeTime, relativeTimeOne)
  File "D:\00 eigene Daten\000 FH\S 4\Regelungstechnik\Regelungsversuch\microRay\gui\plotWidget.py", line 269, in refreshTimeLabels
    self.time0Label.setText(u"t0 {.3f} s".format(time0))
AttributeError: 'float' object has no attribute '3f'

2018-02-10 15:17:09,947 ERROR    uncaught exception
2018-02-10 15:17:09,947 ERROR    
2018-02-10 15:17:09,970 CRITICAL uncaught exception:

Traceback (most recent call last):
  File "D:\00 eigene Daten\000 FH\S 4\Regelungstechnik\Regelungsversuch\microRay\gui\plotWidget.py", line 300, in updatePlots
    self.updateValueLabels()
  File "D:\00 eigene Daten\000 FH\S 4\Regelungstechnik\Regelungsversuch\microRay\gui\plotWidget.py", line 379, in updateValueLabels
    self.refreshTimeLabels(relativeTime, relativeTimeOne)
  File "D:\00 eigene Daten\000 FH\S 4\Regelungstechnik\Regelungsversuch\microRay\gui\plotWidget.py", line 269, in refreshTimeLabels
    self.time0Label.setText(u"t0 {.3f} s".format(time0))
AttributeError: 'float' object has no attribute '3f'

2018-02-10 15:17:09,971 ERROR    uncaught exception
2018-02-10 15:17:09,971 ERROR    
2018-02-10 15:17:10,020 CRITICAL uncaught exception:

Traceback (most recent call last):
  File "D:\00 eigene Daten\000 FH\S 4\Regelungstechnik\Regelungsversuch\microRay\gui\plotWidget.py", line 300, in updatePlots
    self.updateValueLabels()
  File "D:\00 eigene Daten\000 FH\S 4\Regelungstechnik\Regelungsversuch\microRay\gui\plotWidget.py", line 379, in updateValueLabels
    self.refreshTimeLabels(relativeTime, relativeTimeOne)
  File "D:\00 eigene Daten\000 FH\S 4\Regelungstechnik\Regelungsversuch\microRay\gui\plotWidget.py", line 269, in refreshTimeLabels
    self.time0Label.setText(u"t0 {.3f} s".format(time0))
AttributeError: 'float' object has no attribute '3f'

2018-02-10 15:17:10,023 ERROR    uncaught exception
2018-02-10 15:17:10,023 ERROR    
2018-02-10 15:17:10,066 CRITICAL uncaught exception:

Traceback (most recent call last):
  File "D:\00 eigene Daten\000 FH\S 4\Regelungstechnik\Regelungsversuch\microRay\gui\plotWidget.py", line 300, in updatePlots
    self.updateValueLabels()
  File "D:\00 eigene Daten\000 FH\S 4\Regelungstechnik\Regelungsversuch\microRay\gui\plotWidget.py", line 379, in updateValueLabels
    self.refreshTimeLabels(relativeTime, relativeTimeOne)
  File "D:\00 eigene Daten\000 FH\S 4\Regelungstechnik\Regelungsversuch\microRay\gui\plotWidget.py", line 269, in refreshTimeLabels
    self.time0Label.setText(u"t0 {.3f} s".format(time0))
AttributeError: 'float' object has no attribute '3f'

2018-02-10 15:17:10,069 ERROR    uncaught exception
2018-02-10 15:17:10,069 ERROR    
2018-02-10 15:17:10,111 CRITICAL uncaught exception:

Traceback (most recent call last):
  File "D:\00 eigene Daten\000 FH\S 4\Regelungstechnik\Regelungsversuch\microRay\gui\plotWidget.py", line 300, in updatePlots
    self.updateValueLabels()
  File "D:\00 eigene Daten\000 FH\S 4\Regelungstechnik\Regelungsversuch\microRay\gui\plotWidget.py", line 379, in updateValueLabels
    self.refreshTimeLabels(relativeTime, relativeTimeOne)
  File "D:\00 eigene Daten\000 FH\S 4\Regelungstechnik\Regelungsversuch\microRay\gui\plotWidget.py", line 269, in refreshTimeLabels
    self.time0Label.setText(u"t0 {.3f} s".format(time0))
AttributeError: 'float' object has no attribute '3f'

2018-02-10 15:17:10,112 ERROR    uncaught exception
2018-02-10 15:17:10,112 ERROR    
2018-02-10 15:17:10,164 CRITICAL uncaught exception:

Traceback (most recent call last):
  File "D:\00 eigene Daten\000 FH\S 4\Regelungstechnik\Regelungsversuch\microRay\gui\plotWidget.py", line 300, in updatePlots
    self.updateValueLabels()
  File "D:\00 eigene Daten\000 FH\S 4\Regelungstechnik\Regelungsversuch\microRay\gui\plotWidget.py", line 379, in updateValueLabels
    self.refreshTimeLabels(relativeTime, relativeTimeOne)
  File "D:\00 eigene Daten\000 FH\S 4\Regelungstechnik\Regelungsversuch\microRay\gui\plotWidget.py", line 269, in refreshTimeLabels
    self.time0Label.setText(u"t0 {.3f} s".format(time0))
AttributeError: 'float' object has no attribute '3f'

2018-02-10 15:17:10,164 ERROR    uncaught exception
2018-02-10 15:17:10,164 ERROR    
2018-02-10 15:17:10,204 CRITICAL uncaught exception:

Traceback (most recent call last):
  File "D:\00 eigene Daten\000 FH\S 4\Regelungstechnik\Regelungsversuch\microRay\gui\plotWidget.py", line 300, in updatePlots
    self.updateValueLabels()
  File "D:\00 eigene Daten\000 FH\S 4\Regelungstechnik\Regelungsversuch\microRay\gui\plotWidget.py", line 379, in updateValueLabels
    self.refreshTimeLabels(relativeTime, relativeTimeOne)
  File "D:\00 eigene Daten\000 FH\S 4\Regelungstechnik\Regelungsversuch\microRay\gui\plotWidget.py", line 269, in refreshTimeLabels
    self.time0Label.setText(u"t0 {.3f} s".format(time0))
AttributeError: 'float' object has no attribute '3f'

2018-02-10 15:17:10,207 ERROR    uncaught exception
2018-02-10 15:17:10,207 ERROR    
2018-02-10 15:17:10,253 CRITICAL uncaught exception:

Traceback (most recent call last):
  File "D:\00 eigene Daten\000 FH\S 4\Regelungstechnik\Regelungsversuch\microRay\gui\plotWidget.py", line 300, in updatePlots
    self.updateValueLabels()
  File "D:\00 eigene Daten\000 FH\S 4\Regelungstechnik\Regelungsversuch\microRay\gui\plotWidget.py", line 379, in updateValueLabels
    self.refreshTimeLabels(relativeTime, relativeTimeOne)
  File "D:\00 eigene Daten\000 FH\S 4\Regelungstechnik\Regelungsversuch\microRay\gui\plotWidget.py", line 269, in refreshTimeLabels
    self.time0Label.setText(u"t0 {.3f} s".format(time0))
AttributeError: 'float' object has no attribute '3f'

2018-02-10 15:17:10,257 ERROR    uncaught exception
2018-02-10 15:17:10,259 ERROR    
2018-02-10 15:17:10,298 CRITICAL uncaught exception:

Traceback (most recent call last):
  File "D:\00 eigene Daten\000 FH\S 4\Regelungstechnik\Regelungsversuch\microRay\gui\plotWidget.py", line 300, in updatePlots
    self.updateValueLabels()
  File "D:\00 eigene Daten\000 FH\S 4\Regelungstechnik\Regelungsversuch\microRay\gui\plotWidget.py", line 379, in updateValueLabels
    self.refreshTimeLabels(relativeTime, relativeTimeOne)
  File "D:\00 eigene Daten\000 FH\S 4\Regelungstechnik\Regelungsversuch\microRay\gui\plotWidget.py", line 269, in refreshTimeLabels
    self.time0Label.setText(u"t0 {.3f} s".format(time0))
AttributeError: 'float' object has no attribute '3f'

2018-02-10 15:17:10,299 ERROR    uncaught exception
2018-02-10 15:17:10,299 ERROR    
2018-02-10 15:17:10,345 CRITICAL uncaught exception:

Traceback (most recent call last):
  File "D:\00 eigene Daten\000 FH\S 4\Regelungstechnik\Regelungsversuch\microRay\gui\plotWidget.py", line 300, in updatePlots
    self.updateValueLabels()
  File "D:\00 eigene Daten\000 FH\S 4\Regelungstechnik\Regelungsversuch\microRay\gui\plotWidget.py", line 379, in updateValueLabels
    self.refreshTimeLabels(relativeTime, relativeTimeOne)
  File "D:\00 eigene Daten\000 FH\S 4\Regelungstechnik\Regelungsversuch\microRay\gui\plotWidget.py", line 269, in refreshTimeLabels
    self.time0Label.setText(u"t0 {.3f} s".format(time0))
AttributeError: 'float' object has no attribute '3f'

2018-02-10 15:17:10,348 ERROR    uncaught exception
2018-02-10 15:17:10,348 ERROR    
2018-02-10 15:17:10,394 CRITICAL uncaught exception:

Traceback (most recent call last):
  File "D:\00 eigene Daten\000 FH\S 4\Regelungstechnik\Regelungsversuch\microRay\gui\plotWidget.py", line 300, in updatePlots
    self.updateValueLabels()
  File "D:\00 eigene Daten\000 FH\S 4\Regelungstechnik\Regelungsversuch\microRay\gui\plotWidget.py", line 379, in updateValueLabels
    self.refreshTimeLabels(relativeTime, relativeTimeOne)
  File "D:\00 eigene Daten\000 FH\S 4\Regelungstechnik\Regelungsversuch\microRay\gui\plotWidget.py", line 269, in refreshTimeLabels
    self.time0Label.setText(u"t0 {.3f} s".format(time0))
AttributeError: 'float' object has no attribute '3f'

2018-02-10 15:17:10,395 ERROR    uncaught exception
2018-02-10 15:17:10,395 ERROR    
2018-02-10 15:17:10,441 CRITICAL uncaught exception:

Traceback (most recent call last):
  File "D:\00 eigene Daten\000 FH\S 4\Regelungstechnik\Regelungsversuch\microRay\gui\plotWidget.py", line 300, in updatePlots
    self.updateValueLabels()
  File "D:\00 eigene Daten\000 FH\S 4\Regelungstechnik\Regelungsversuch\microRay\gui\plotWidget.py", line 379, in updateValueLabels
    self.refreshTimeLabels(relativeTime, relativeTimeOne)
  File "D:\00 eigene Daten\000 FH\S 4\Regelungstechnik\Regelungsversuch\microRay\gui\plotWidget.py", line 269, in refreshTimeLabels
    self.time0Label.setText(u"t0 {.3f} s".format(time0))
AttributeError: 'float' object has no attribute '3f'

2018-02-10 15:17:10,444 ERROR    uncaught exception
2018-02-10 15:17:10,444 ERROR    
2018-02-10 15:17:10,483 CRITICAL uncaught exception:

Traceback (most recent call last):
  File "D:\00 eigene Daten\000 FH\S 4\Regelungstechnik\Regelungsversuch\microRay\gui\plotWidget.py", line 300, in updatePlots
    self.updateValueLabels()
  File "D:\00 eigene Daten\000 FH\S 4\Regelungstechnik\Regelungsversuch\microRay\gui\plotWidget.py", line 379, in updateValueLabels
    self.refreshTimeLabels(relativeTime, relativeTimeOne)
  File "D:\00 eigene Daten\000 FH\S 4\Regelungstechnik\Regelungsversuch\microRay\gui\plotWidget.py", line 269, in refreshTimeLabels
    self.time0Label.setText(u"t0 {.3f} s".format(time0))
AttributeError: 'float' object has no attribute '3f'

2018-02-10 15:17:10,486 ERROR    uncaught exception
2018-02-10 15:17:10,486 ERROR    
2018-02-10 15:17:10,530 CRITICAL uncaught exception:

Traceback (most recent call last):
  File "D:\00 eigene Daten\000 FH\S 4\Regelungstechnik\Regelungsversuch\microRay\gui\plotWidget.py", line 300, in updatePlots
    self.updateValueLabels()
  File "D:\00 eigene Daten\000 FH\S 4\Regelungstechnik\Regelungsversuch\microRay\gui\plotWidget.py", line 379, in updateValueLabels
    self.refreshTimeLabels(relativeTime, relativeTimeOne)
  File "D:\00 eigene Daten\000 FH\S 4\Regelungstechnik\Regelungsversuch\microRay\gui\plotWidget.py", line 269, in refreshTimeLabels
    self.time0Label.setText(u"t0 {.3f} s".format(time0))
AttributeError: 'float' object has no attribute '3f'

2018-02-10 15:17:10,532 ERROR    uncaught exception
2018-02-10 15:17:10,532 ERROR    
2018-02-10 15:17:10,585 CRITICAL uncaught exception:

Traceback (most recent call last):
  File "D:\00 eigene Daten\000 FH\S 4\Regelungstechnik\Regelungsversuch\microRay\gui\plotWidget.py", line 300, in updatePlots
    self.updateValueLabels()
  File "D:\00 eigene Daten\000 FH\S 4\Regelungstechnik\Regelungsversuch\microRay\gui\plotWidget.py", line 379, in updateValueLabels
    self.refreshTimeLabels(relativeTime, relativeTimeOne)
  File "D:\00 eigene Daten\000 FH\S 4\Regelungstechnik\Regelungsversuch\microRay\gui\plotWidget.py", line 269, in refreshTimeLabels
    self.time0Label.setText(u"t0 {.3f} s".format(time0))
AttributeError: 'float' object has no attribute '3f'

2018-02-10 15:17:10,588 ERROR    uncaught exception
2018-02-10 15:17:10,588 ERROR    
2018-02-10 15:17:10,631 CRITICAL uncaught exception:

Traceback (most recent call last):
  File "D:\00 eigene Daten\000 FH\S 4\Regelungstechnik\Regelungsversuch\microRay\gui\plotWidget.py", line 300, in updatePlots
    self.updateValueLabels()
  File "D:\00 eigene Daten\000 FH\S 4\Regelungstechnik\Regelungsversuch\microRay\gui\plotWidget.py", line 379, in updateValueLabels
    self.refreshTimeLabels(relativeTime, relativeTimeOne)
  File "D:\00 eigene Daten\000 FH\S 4\Regelungstechnik\Regelungsversuch\microRay\gui\plotWidget.py", line 269, in refreshTimeLabels
    self.time0Label.setText(u"t0 {.3f} s".format(time0))
AttributeError: 'float' object has no attribute '3f'

2018-02-10 15:17:10,631 ERROR    uncaught exception
2018-02-10 15:17:10,631 ERROR    
2018-02-10 15:17:10,676 CRITICAL uncaught exception:

Traceback (most recent call last):
  File "D:\00 eigene Daten\000 FH\S 4\Regelungstechnik\Regelungsversuch\microRay\gui\plotWidget.py", line 300, in updatePlots
    self.updateValueLabels()
  File "D:\00 eigene Daten\000 FH\S 4\Regelungstechnik\Regelungsversuch\microRay\gui\plotWidget.py", line 379, in updateValueLabels
    self.refreshTimeLabels(relativeTime, relativeTimeOne)
  File "D:\00 eigene Daten\000 FH\S 4\Regelungstechnik\Regelungsversuch\microRay\gui\plotWidget.py", line 269, in refreshTimeLabels
    self.time0Label.setText(u"t0 {.3f} s".format(time0))
AttributeError: 'float' object has no attribute '3f'

2018-02-10 15:17:10,677 ERROR    uncaught exception
2018-02-10 15:17:10,677 ERROR    
2018-02-10 15:17:10,729 CRITICAL uncaught exception:

Traceback (most recent call last):
  File "D:\00 eigene Daten\000 FH\S 4\Regelungstechnik\Regelungsversuch\microRay\gui\plotWidget.py", line 300, in updatePlots
    self.updateValueLabels()
  File "D:\00 eigene Daten\000 FH\S 4\Regelungstechnik\Regelungsversuch\microRay\gui\plotWidget.py", line 379, in updateValueLabels
    self.refreshTimeLabels(relativeTime, relativeTimeOne)
  File "D:\00 eigene Daten\000 FH\S 4\Regelungstechnik\Regelungsversuch\microRay\gui\plotWidget.py", line 269, in refreshTimeLabels
    self.time0Label.setText(u"t0 {.3f} s".format(time0))
AttributeError: 'float' object has no attribute '3f'

2018-02-10 15:17:10,730 ERROR    uncaught exception
2018-02-10 15:17:10,730 ERROR    
2018-02-10 15:17:10,769 CRITICAL uncaught exception:

Traceback (most recent call last):
  File "D:\00 eigene Daten\000 FH\S 4\Regelungstechnik\Regelungsversuch\microRay\gui\plotWidget.py", line 300, in updatePlots
    self.updateValueLabels()
  File "D:\00 eigene Daten\000 FH\S 4\Regelungstechnik\Regelungsversuch\microRay\gui\plotWidget.py", line 379, in updateValueLabels
    self.refreshTimeLabels(relativeTime, relativeTimeOne)
  File "D:\00 eigene Daten\000 FH\S 4\Regelungstechnik\Regelungsversuch\microRay\gui\plotWidget.py", line 269, in refreshTimeLabels
    self.time0Label.setText(u"t0 {.3f} s".format(time0))
AttributeError: 'float' object has no attribute '3f'

2018-02-10 15:17:10,769 ERROR    uncaught exception
2018-02-10 15:17:10,770 ERROR    
2018-02-10 15:17:10,819 CRITICAL uncaught exception:

Traceback (most recent call last):
  File "D:\00 eigene Daten\000 FH\S 4\Regelungstechnik\Regelungsversuch\microRay\gui\plotWidget.py", line 300, in updatePlots
    self.updateValueLabels()
  File "D:\00 eigene Daten\000 FH\S 4\Regelungstechnik\Regelungsversuch\microRay\gui\plotWidget.py", line 379, in updateValueLabels
    self.refreshTimeLabels(relativeTime, relativeTimeOne)
  File "D:\00 eigene Daten\000 FH\S 4\Regelungstechnik\Regelungsversuch\microRay\gui\plotWidget.py", line 269, in refreshTimeLabels
    self.time0Label.setText(u"t0 {.3f} s".format(time0))
AttributeError: 'float' object has no attribute '3f'

2018-02-10 15:17:10,821 ERROR    uncaught exception
2018-02-10 15:17:10,822 ERROR    
2018-02-10 15:17:10,861 CRITICAL uncaught exception:

Traceback (most recent call last):
  File "D:\00 eigene Daten\000 FH\S 4\Regelungstechnik\Regelungsversuch\microRay\gui\plotWidget.py", line 300, in updatePlots
    self.updateValueLabels()
  File "D:\00 eigene Daten\000 FH\S 4\Regelungstechnik\Regelungsversuch\microRay\gui\plotWidget.py", line 379, in updateValueLabels
    self.refreshTimeLabels(relativeTime, relativeTimeOne)
  File "D:\00 eigene Daten\000 FH\S 4\Regelungstechnik\Regelungsversuch\microRay\gui\plotWidget.py", line 269, in refreshTimeLabels
    self.time0Label.setText(u"t0 {.3f} s".format(time0))
AttributeError: 'float' object has no attribute '3f'

2018-02-10 15:17:10,862 ERROR    uncaught exception
2018-02-10 15:17:10,862 ERROR    
2018-02-10 15:17:10,905 CRITICAL uncaught exception:

Traceback (most recent call last):
  File "D:\00 eigene Daten\000 FH\S 4\Regelungstechnik\Regelungsversuch\microRay\gui\plotWidget.py", line 300, in updatePlots
    self.updateValueLabels()
  File "D:\00 eigene Daten\000 FH\S 4\Regelungstechnik\Regelungsversuch\microRay\gui\plotWidget.py", line 379, in updateValueLabels
    self.refreshTimeLabels(relativeTime, relativeTimeOne)
  File "D:\00 eigene Daten\000 FH\S 4\Regelungstechnik\Regelungsversuch\microRay\gui\plotWidget.py", line 269, in refreshTimeLabels
    self.time0Label.setText(u"t0 {.3f} s".format(time0))
AttributeError: 'float' object has no attribute '3f'

2018-02-10 15:17:10,907 ERROR    uncaught exception
2018-02-10 15:17:10,907 ERROR    
2018-02-10 15:17:10,956 CRITICAL uncaught exception:

Traceback (most recent call last):
  File "D:\00 eigene Daten\000 FH\S 4\Regelungstechnik\Regelungsversuch\microRay\gui\plotWidget.py", line 300, in updatePlots
    self.updateValueLabels()
  File "D:\00 eigene Daten\000 FH\S 4\Regelungstechnik\Regelungsversuch\microRay\gui\plotWidget.py", line 379, in updateValueLabels
    self.refreshTimeLabels(relativeTime, relativeTimeOne)
  File "D:\00 eigene Daten\000 FH\S 4\Regelungstechnik\Regelungsversuch\microRay\gui\plotWidget.py", line 269, in refreshTimeLabels
    self.time0Label.setText(u"t0 {.3f} s".format(time0))
AttributeError: 'float' object has no attribute '3f'

2018-02-10 15:17:10,957 ERROR    uncaught exception
2018-02-10 15:17:10,957 ERROR    
2018-02-10 15:17:11,002 CRITICAL uncaught exception:

Traceback (most recent call last):
  File "D:\00 eigene Daten\000 FH\S 4\Regelungstechnik\Regelungsversuch\microRay\gui\plotWidget.py", line 300, in updatePlots
    self.updateValueLabels()
  File "D:\00 eigene Daten\000 FH\S 4\Regelungstechnik\Regelungsversuch\microRay\gui\plotWidget.py", line 379, in updateValueLabels
    self.refreshTimeLabels(relativeTime, relativeTimeOne)
  File "D:\00 eigene Daten\000 FH\S 4\Regelungstechnik\Regelungsversuch\microRay\gui\plotWidget.py", line 269, in refreshTimeLabels
    self.time0Label.setText(u"t0 {.3f} s".format(time0))
AttributeError: 'float' object has no attribute '3f'

2018-02-10 15:17:11,003 ERROR    uncaught exception
2018-02-10 15:17:11,003 ERROR    
2018-02-10 15:17:11,046 CRITICAL uncaught exception:

Traceback (most recent call last):
  File "D:\00 eigene Daten\000 FH\S 4\Regelungstechnik\Regelungsversuch\microRay\gui\plotWidget.py", line 300, in updatePlots
    self.updateValueLabels()
  File "D:\00 eigene Daten\000 FH\S 4\Regelungstechnik\Regelungsversuch\microRay\gui\plotWidget.py", line 379, in updateValueLabels
    self.refreshTimeLabels(relativeTime, relativeTimeOne)
  File "D:\00 eigene Daten\000 FH\S 4\Regelungstechnik\Regelungsversuch\microRay\gui\plotWidget.py", line 269, in refreshTimeLabels
    self.time0Label.setText(u"t0 {.3f} s".format(time0))
AttributeError: 'float' object has no attribute '3f'

2018-02-10 15:17:11,048 ERROR    uncaught exception
2018-02-10 15:17:11,048 ERROR    
2018-02-10 15:17:11,099 CRITICAL uncaught exception:

Traceback (most recent call last):
  File "D:\00 eigene Daten\000 FH\S 4\Regelungstechnik\Regelungsversuch\microRay\gui\plotWidget.py", line 300, in updatePlots
    self.updateValueLabels()
  File "D:\00 eigene Daten\000 FH\S 4\Regelungstechnik\Regelungsversuch\microRay\gui\plotWidget.py", line 379, in updateValueLabels
    self.refreshTimeLabels(relativeTime, relativeTimeOne)
  File "D:\00 eigene Daten\000 FH\S 4\Regelungstechnik\Regelungsversuch\microRay\gui\plotWidget.py", line 269, in refreshTimeLabels
    self.time0Label.setText(u"t0 {.3f} s".format(time0))
AttributeError: 'float' object has no attribute '3f'

2018-02-10 15:17:11,101 ERROR    uncaught exception
2018-02-10 15:17:11,101 ERROR    
2018-02-10 15:17:11,150 CRITICAL uncaught exception:

Traceback (most recent call last):
  File "D:\00 eigene Daten\000 FH\S 4\Regelungstechnik\Regelungsversuch\microRay\gui\plotWidget.py", line 300, in updatePlots
    self.updateValueLabels()
  File "D:\00 eigene Daten\000 FH\S 4\Regelungstechnik\Regelungsversuch\microRay\gui\plotWidget.py", line 379, in updateValueLabels
    self.refreshTimeLabels(relativeTime, relativeTimeOne)
  File "D:\00 eigene Daten\000 FH\S 4\Regelungstechnik\Regelungsversuch\microRay\gui\plotWidget.py", line 269, in refreshTimeLabels
    self.time0Label.setText(u"t0 {.3f} s".format(time0))
AttributeError: 'float' object has no attribute '3f'

2018-02-10 15:17:11,151 ERROR    uncaught exception
2018-02-10 15:17:11,151 ERROR    
2018-02-10 15:17:11,194 CRITICAL uncaught exception:

Traceback (most recent call last):
  File "D:\00 eigene Daten\000 FH\S 4\Regelungstechnik\Regelungsversuch\microRay\gui\plotWidget.py", line 300, in updatePlots
    self.updateValueLabels()
  File "D:\00 eigene Daten\000 FH\S 4\Regelungstechnik\Regelungsversuch\microRay\gui\plotWidget.py", line 379, in updateValueLabels
    self.refreshTimeLabels(relativeTime, relativeTimeOne)
  File "D:\00 eigene Daten\000 FH\S 4\Regelungstechnik\Regelungsversuch\microRay\gui\plotWidget.py", line 269, in refreshTimeLabels
    self.time0Label.setText(u"t0 {.3f} s".format(time0))
AttributeError: 'float' object has no attribute '3f'

2018-02-10 15:17:11,197 ERROR    uncaught exception
2018-02-10 15:17:11,197 ERROR    
2018-02-10 15:17:11,236 CRITICAL uncaught exception:

Traceback (most recent call last):
  File "D:\00 eigene Daten\000 FH\S 4\Regelungstechnik\Regelungsversuch\microRay\gui\plotWidget.py", line 300, in updatePlots
    self.updateValueLabels()
  File "D:\00 eigene Daten\000 FH\S 4\Regelungstechnik\Regelungsversuch\microRay\gui\plotWidget.py", line 379, in updateValueLabels
    self.refreshTimeLabels(relativeTime, relativeTimeOne)
  File "D:\00 eigene Daten\000 FH\S 4\Regelungstechnik\Regelungsversuch\microRay\gui\plotWidget.py", line 269, in refreshTimeLabels
    self.time0Label.setText(u"t0 {.3f} s".format(time0))
AttributeError: 'float' object has no attribute '3f'

2018-02-10 15:17:11,237 ERROR    uncaught exception
2018-02-10 15:17:11,237 ERROR    
2018-02-10 15:17:11,286 CRITICAL uncaught exception:

Traceback (most recent call last):
  File "D:\00 eigene Daten\000 FH\S 4\Regelungstechnik\Regelungsversuch\microRay\gui\plotWidget.py", line 300, in updatePlots
    self.updateValueLabels()
  File "D:\00 eigene Daten\000 FH\S 4\Regelungstechnik\Regelungsversuch\microRay\gui\plotWidget.py", line 379, in updateValueLabels
    self.refreshTimeLabels(relativeTime, relativeTimeOne)
  File "D:\00 eigene Daten\000 FH\S 4\Regelungstechnik\Regelungsversuch\microRay\gui\plotWidget.py", line 269, in refreshTimeLabels
    self.time0Label.setText(u"t0 {.3f} s".format(time0))
AttributeError: 'float' object has no attribute '3f'

2018-02-10 15:17:11,290 ERROR    uncaught exception
2018-02-10 15:17:11,292 ERROR    
2018-02-10 15:17:11,334 CRITICAL uncaught exception:

Traceback (most recent call last):
  File "D:\00 eigene Daten\000 FH\S 4\Regelungstechnik\Regelungsversuch\microRay\gui\plotWidget.py", line 300, in updatePlots
    self.updateValueLabels()
  File "D:\00 eigene Daten\000 FH\S 4\Regelungstechnik\Regelungsversuch\microRay\gui\plotWidget.py", line 379, in updateValueLabels
    self.refreshTimeLabels(relativeTime, relativeTimeOne)
  File "D:\00 eigene Daten\000 FH\S 4\Regelungstechnik\Regelungsversuch\microRay\gui\plotWidget.py", line 269, in refreshTimeLabels
    self.time0Label.setText(u"t0 {.3f} s".format(time0))
AttributeError: 'float' object has no attribute '3f'

2018-02-10 15:17:11,336 ERROR    uncaught exception
2018-02-10 15:17:11,338 ERROR    
2018-02-10 15:17:11,377 CRITICAL uncaught exception:

Traceback (most recent call last):
  File "D:\00 eigene Daten\000 FH\S 4\Regelungstechnik\Regelungsversuch\microRay\gui\plotWidget.py", line 300, in updatePlots
    self.updateValueLabels()
  File "D:\00 eigene Daten\000 FH\S 4\Regelungstechnik\Regelungsversuch\microRay\gui\plotWidget.py", line 379, in updateValueLabels
    self.refreshTimeLabels(relativeTime, relativeTimeOne)
  File "D:\00 eigene Daten\000 FH\S 4\Regelungstechnik\Regelungsversuch\microRay\gui\plotWidget.py", line 269, in refreshTimeLabels
    self.time0Label.setText(u"t0 {.3f} s".format(time0))
AttributeError: 'float' object has no attribute '3f'

2018-02-10 15:17:11,378 ERROR    uncaught exception
2018-02-10 15:17:11,378 ERROR    
2018-02-10 15:17:11,423 CRITICAL uncaught exception:

Traceback (most recent call last):
  File "D:\00 eigene Daten\000 FH\S 4\Regelungstechnik\Regelungsversuch\microRay\gui\plotWidget.py", line 300, in updatePlots
    self.updateValueLabels()
  File "D:\00 eigene Daten\000 FH\S 4\Regelungstechnik\Regelungsversuch\microRay\gui\plotWidget.py", line 379, in updateValueLabels
    self.refreshTimeLabels(relativeTime, relativeTimeOne)
  File "D:\00 eigene Daten\000 FH\S 4\Regelungstechnik\Regelungsversuch\microRay\gui\plotWidget.py", line 269, in refreshTimeLabels
    self.time0Label.setText(u"t0 {.3f} s".format(time0))
AttributeError: 'float' object has no attribute '3f'

2018-02-10 15:17:11,424 ERROR    uncaught exception
2018-02-10 15:17:11,424 ERROR    
2018-02-10 15:17:11,470 CRITICAL uncaught exception:

Traceback (most recent call last):
  File "D:\00 eigene Daten\000 FH\S 4\Regelungstechnik\Regelungsversuch\microRay\gui\plotWidget.py", line 300, in updatePlots
    self.updateValueLabels()
  File "D:\00 eigene Daten\000 FH\S 4\Regelungstechnik\Regelungsversuch\microRay\gui\plotWidget.py", line 379, in updateValueLabels
    self.refreshTimeLabels(relativeTime, relativeTimeOne)
  File "D:\00 eigene Daten\000 FH\S 4\Regelungstechnik\Regelungsversuch\microRay\gui\plotWidget.py", line 269, in refreshTimeLabels
    self.time0Label.setText(u"t0 {.3f} s".format(time0))
AttributeError: 'float' object has no attribute '3f'

2018-02-10 15:17:11,473 ERROR    uncaught exception
2018-02-10 15:17:11,474 ERROR    
2018-02-10 15:17:11,523 CRITICAL uncaught exception:

Traceback (most recent call last):
  File "D:\00 eigene Daten\000 FH\S 4\Regelungstechnik\Regelungsversuch\microRay\gui\plotWidget.py", line 300, in updatePlots
    self.updateValueLabels()
  File "D:\00 eigene Daten\000 FH\S 4\Regelungstechnik\Regelungsversuch\microRay\gui\plotWidget.py", line 379, in updateValueLabels
    self.refreshTimeLabels(relativeTime, relativeTimeOne)
  File "D:\00 eigene Daten\000 FH\S 4\Regelungstechnik\Regelungsversuch\microRay\gui\plotWidget.py", line 269, in refreshTimeLabels
    self.time0Label.setText(u"t0 {.3f} s".format(time0))
AttributeError: 'float' object has no attribute '3f'

2018-02-10 15:17:11,525 ERROR    uncaught exception
2018-02-10 15:17:11,525 ERROR    
2018-02-10 15:17:11,625 CRITICAL uncaught exception:

Traceback (most recent call last):
  File "D:\00 eigene Daten\000 FH\S 4\Regelungstechnik\Regelungsversuch\microRay\gui\plotWidget.py", line 300, in updatePlots
    self.updateValueLabels()
  File "D:\00 eigene Daten\000 FH\S 4\Regelungstechnik\Regelungsversuch\microRay\gui\plotWidget.py", line 379, in updateValueLabels
    self.refreshTimeLabels(relativeTime, relativeTimeOne)
  File "D:\00 eigene Daten\000 FH\S 4\Regelungstechnik\Regelungsversuch\microRay\gui\plotWidget.py", line 269, in refreshTimeLabels
    self.time0Label.setText(u"t0 {.3f} s".format(time0))
AttributeError: 'float' object has no attribute '3f'

2018-02-10 15:17:11,628 ERROR    uncaught exception
2018-02-10 15:17:11,628 ERROR    
2018-02-10 15:17:11,680 CRITICAL uncaught exception:

Traceback (most recent call last):
  File "D:\00 eigene Daten\000 FH\S 4\Regelungstechnik\Regelungsversuch\microRay\gui\plotWidget.py", line 300, in updatePlots
    self.updateValueLabels()
  File "D:\00 eigene Daten\000 FH\S 4\Regelungstechnik\Regelungsversuch\microRay\gui\plotWidget.py", line 379, in updateValueLabels
    self.refreshTimeLabels(relativeTime, relativeTimeOne)
  File "D:\00 eigene Daten\000 FH\S 4\Regelungstechnik\Regelungsversuch\microRay\gui\plotWidget.py", line 269, in refreshTimeLabels
    self.time0Label.setText(u"t0 {.3f} s".format(time0))
AttributeError: 'float' object has no attribute '3f'

2018-02-10 15:17:11,681 ERROR    uncaught exception
2018-02-10 15:17:11,681 ERROR    
2018-02-10 15:17:11,726 CRITICAL uncaught exception:

Traceback (most recent call last):
  File "D:\00 eigene Daten\000 FH\S 4\Regelungstechnik\Regelungsversuch\microRay\gui\plotWidget.py", line 300, in updatePlots
    self.updateValueLabels()
  File "D:\00 eigene Daten\000 FH\S 4\Regelungstechnik\Regelungsversuch\microRay\gui\plotWidget.py", line 379, in updateValueLabels
    self.refreshTimeLabels(relativeTime, relativeTimeOne)
  File "D:\00 eigene Daten\000 FH\S 4\Regelungstechnik\Regelungsversuch\microRay\gui\plotWidget.py", line 269, in refreshTimeLabels
    self.time0Label.setText(u"t0 {.3f} s".format(time0))
AttributeError: 'float' object has no attribute '3f'

2018-02-10 15:17:11,727 ERROR    uncaught exception
2018-02-10 15:17:11,729 ERROR    
2018-02-10 15:17:11,765 CRITICAL uncaught exception:

Traceback (most recent call last):
  File "D:\00 eigene Daten\000 FH\S 4\Regelungstechnik\Regelungsversuch\microRay\gui\plotWidget.py", line 300, in updatePlots
    self.updateValueLabels()
  File "D:\00 eigene Daten\000 FH\S 4\Regelungstechnik\Regelungsversuch\microRay\gui\plotWidget.py", line 379, in updateValueLabels
    self.refreshTimeLabels(relativeTime, relativeTimeOne)
  File "D:\00 eigene Daten\000 FH\S 4\Regelungstechnik\Regelungsversuch\microRay\gui\plotWidget.py", line 269, in refreshTimeLabels
    self.time0Label.setText(u"t0 {.3f} s".format(time0))
AttributeError: 'float' object has no attribute '3f'

2018-02-10 15:17:11,766 ERROR    uncaught exception
2018-02-10 15:17:11,766 ERROR    
2018-02-10 15:17:11,819 CRITICAL uncaught exception:

Traceback (most recent call last):
  File "D:\00 eigene Daten\000 FH\S 4\Regelungstechnik\Regelungsversuch\microRay\gui\plotWidget.py", line 300, in updatePlots
    self.updateValueLabels()
  File "D:\00 eigene Daten\000 FH\S 4\Regelungstechnik\Regelungsversuch\microRay\gui\plotWidget.py", line 379, in updateValueLabels
    self.refreshTimeLabels(relativeTime, relativeTimeOne)
  File "D:\00 eigene Daten\000 FH\S 4\Regelungstechnik\Regelungsversuch\microRay\gui\plotWidget.py", line 269, in refreshTimeLabels
    self.time0Label.setText(u"t0 {.3f} s".format(time0))
AttributeError: 'float' object has no attribute '3f'

2018-02-10 15:17:11,822 ERROR    uncaught exception
2018-02-10 15:17:11,822 ERROR    
2018-02-10 15:17:11,859 CRITICAL uncaught exception:

Traceback (most recent call last):
  File "D:\00 eigene Daten\000 FH\S 4\Regelungstechnik\Regelungsversuch\microRay\gui\plotWidget.py", line 300, in updatePlots
    self.updateValueLabels()
  File "D:\00 eigene Daten\000 FH\S 4\Regelungstechnik\Regelungsversuch\microRay\gui\plotWidget.py", line 379, in updateValueLabels
    self.refreshTimeLabels(relativeTime, relativeTimeOne)
  File "D:\00 eigene Daten\000 FH\S 4\Regelungstechnik\Regelungsversuch\microRay\gui\plotWidget.py", line 269, in refreshTimeLabels
    self.time0Label.setText(u"t0 {.3f} s".format(time0))
AttributeError: 'float' object has no attribute '3f'

2018-02-10 15:17:11,861 ERROR    uncaught exception
2018-02-10 15:17:11,861 ERROR    
2018-02-10 15:17:11,910 CRITICAL uncaught exception:

Traceback (most recent call last):
  File "D:\00 eigene Daten\000 FH\S 4\Regelungstechnik\Regelungsversuch\microRay\gui\plotWidget.py", line 300, in updatePlots
    self.updateValueLabels()
  File "D:\00 eigene Daten\000 FH\S 4\Regelungstechnik\Regelungsversuch\microRay\gui\plotWidget.py", line 379, in updateValueLabels
    self.refreshTimeLabels(relativeTime, relativeTimeOne)
  File "D:\00 eigene Daten\000 FH\S 4\Regelungstechnik\Regelungsversuch\microRay\gui\plotWidget.py", line 269, in refreshTimeLabels
    self.time0Label.setText(u"t0 {.3f} s".format(time0))
AttributeError: 'float' object has no attribute '3f'

2018-02-10 15:17:11,911 ERROR    uncaught exception
2018-02-10 15:17:11,911 ERROR    
2018-02-10 15:17:11,957 CRITICAL uncaught exception:

Traceback (most recent call last):
  File "D:\00 eigene Daten\000 FH\S 4\Regelungstechnik\Regelungsversuch\microRay\gui\plotWidget.py", line 300, in updatePlots
    self.updateValueLabels()
  File "D:\00 eigene Daten\000 FH\S 4\Regelungstechnik\Regelungsversuch\microRay\gui\plotWidget.py", line 379, in updateValueLabels
    self.refreshTimeLabels(relativeTime, relativeTimeOne)
  File "D:\00 eigene Daten\000 FH\S 4\Regelungstechnik\Regelungsversuch\microRay\gui\plotWidget.py", line 269, in refreshTimeLabels
    self.time0Label.setText(u"t0 {.3f} s".format(time0))
AttributeError: 'float' object has no attribute '3f'

2018-02-10 15:17:11,960 ERROR    uncaught exception
2018-02-10 15:17:11,960 ERROR    
2018-02-10 15:17:12,003 CRITICAL uncaught exception:

Traceback (most recent call last):
  File "D:\00 eigene Daten\000 FH\S 4\Regelungstechnik\Regelungsversuch\microRay\gui\plotWidget.py", line 300, in updatePlots
    self.updateValueLabels()
  File "D:\00 eigene Daten\000 FH\S 4\Regelungstechnik\Regelungsversuch\microRay\gui\plotWidget.py", line 379, in updateValueLabels
    self.refreshTimeLabels(relativeTime, relativeTimeOne)
  File "D:\00 eigene Daten\000 FH\S 4\Regelungstechnik\Regelungsversuch\microRay\gui\plotWidget.py", line 269, in refreshTimeLabels
    self.time0Label.setText(u"t0 {.3f} s".format(time0))
AttributeError: 'float' object has no attribute '3f'

2018-02-10 15:17:12,005 ERROR    uncaught exception
2018-02-10 15:17:12,005 ERROR    
2018-02-10 15:17:12,046 CRITICAL uncaught exception:

Traceback (most recent call last):
  File "D:\00 eigene Daten\000 FH\S 4\Regelungstechnik\Regelungsversuch\microRay\gui\plotWidget.py", line 300, in updatePlots
    self.updateValueLabels()
  File "D:\00 eigene Daten\000 FH\S 4\Regelungstechnik\Regelungsversuch\microRay\gui\plotWidget.py", line 379, in updateValueLabels
    self.refreshTimeLabels(relativeTime, relativeTimeOne)
  File "D:\00 eigene Daten\000 FH\S 4\Regelungstechnik\Regelungsversuch\microRay\gui\plotWidget.py", line 269, in refreshTimeLabels
    self.time0Label.setText(u"t0 {.3f} s".format(time0))
AttributeError: 'float' object has no attribute '3f'

2018-02-10 15:17:12,049 ERROR    uncaught exception
2018-02-10 15:17:12,049 ERROR    
2018-02-10 15:17:12,098 CRITICAL uncaught exception:

Traceback (most recent call last):
  File "D:\00 eigene Daten\000 FH\S 4\Regelungstechnik\Regelungsversuch\microRay\gui\plotWidget.py", line 300, in updatePlots
    self.updateValueLabels()
  File "D:\00 eigene Daten\000 FH\S 4\Regelungstechnik\Regelungsversuch\microRay\gui\plotWidget.py", line 379, in updateValueLabels
    self.refreshTimeLabels(relativeTime, relativeTimeOne)
  File "D:\00 eigene Daten\000 FH\S 4\Regelungstechnik\Regelungsversuch\microRay\gui\plotWidget.py", line 269, in refreshTimeLabels
    self.time0Label.setText(u"t0 {.3f} s".format(time0))
AttributeError: 'float' object has no attribute '3f'

2018-02-10 15:17:12,102 ERROR    uncaught exception
