2018-02-17 14:37:56,832 CRITICAL uncaught exception:

Traceback (most recent call last):
  File "D:\00 eigene Daten\000 FH\S 4\Regelungstechnik\Regelungsversuch\microRay\gui\plotWidget.py", line 300, in updatePlots
    self.updateValueLabels()
  File "D:\00 eigene Daten\000 FH\S 4\Regelungstechnik\Regelungsversuch\microRay\gui\plotWidget.py", line 347, in updateValueLabels
    xData, yData = firstCurve.getData()
AttributeError: 'NoneType' object has no attribute 'getData'

2018-02-17 14:37:56,881 ERROR    uncaught exception
2018-02-17 14:37:56,881 ERROR    
2018-02-17 14:37:56,920 CRITICAL uncaught exception:

Traceback (most recent call last):
  File "D:\00 eigene Daten\000 FH\S 4\Regelungstechnik\Regelungsversuch\microRay\gui\plotWidget.py", line 300, in updatePlots
    self.updateValueLabels()
  File "D:\00 eigene Daten\000 FH\S 4\Regelungstechnik\Regelungsversuch\microRay\gui\plotWidget.py", line 347, in updateValueLabels
    xData, yData = firstCurve.getData()
AttributeError: 'NoneType' object has no attribute 'getData'

2018-02-17 14:37:56,946 ERROR    uncaught exception
2018-02-17 14:37:56,947 ERROR    
2018-02-17 14:37:56,970 CRITICAL uncaught exception:

Traceback (most recent call last):
  File "D:\00 eigene Daten\000 FH\S 4\Regelungstechnik\Regelungsversuch\microRay\gui\plotWidget.py", line 300, in updatePlots
    self.updateValueLabels()
  File "D:\00 eigene Daten\000 FH\S 4\Regelungstechnik\Regelungsversuch\microRay\gui\plotWidget.py", line 347, in updateValueLabels
    xData, yData = firstCurve.getData()
AttributeError: 'NoneType' object has no attribute 'getData'

2018-02-17 14:37:56,993 ERROR    uncaught exception
2018-02-17 14:37:56,994 ERROR    
2018-02-17 14:37:57,016 CRITICAL uncaught exception:

Traceback (most recent call last):
  File "D:\00 eigene Daten\000 FH\S 4\Regelungstechnik\Regelungsversuch\microRay\gui\plotWidget.py", line 300, in updatePlots
    self.updateValueLabels()
  File "D:\00 eigene Daten\000 FH\S 4\Regelungstechnik\Regelungsversuch\microRay\gui\plotWidget.py", line 347, in updateValueLabels
    xData, yData = firstCurve.getData()
AttributeError: 'NoneType' object has no attribute 'getData'

2018-02-17 14:37:57,040 ERROR    uncaught exception
2018-02-17 14:37:57,040 ERROR    
2018-02-17 14:37:57,065 CRITICAL uncaught exception:

Traceback (most recent call last):
  File "D:\00 eigene Daten\000 FH\S 4\Regelungstechnik\Regelungsversuch\microRay\gui\plotWidget.py", line 300, in updatePlots
    self.updateValueLabels()
  File "D:\00 eigene Daten\000 FH\S 4\Regelungstechnik\Regelungsversuch\microRay\gui\plotWidget.py", line 347, in updateValueLabels
    xData, yData = firstCurve.getData()
AttributeError: 'NoneType' object has no attribute 'getData'

2018-02-17 14:37:57,107 ERROR    uncaught exception
2018-02-17 14:37:57,107 ERROR    
2018-02-17 14:37:57,155 CRITICAL uncaught exception:

Traceback (most recent call last):
  File "D:\00 eigene Daten\000 FH\S 4\Regelungstechnik\Regelungsversuch\microRay\gui\plotWidget.py", line 300, in updatePlots
    self.updateValueLabels()
  File "D:\00 eigene Daten\000 FH\S 4\Regelungstechnik\Regelungsversuch\microRay\gui\plotWidget.py", line 347, in updateValueLabels
    xData, yData = firstCurve.getData()
AttributeError: 'NoneType' object has no attribute 'getData'

2018-02-17 14:37:57,180 ERROR    uncaught exception
2018-02-17 14:37:57,180 ERROR    
2018-02-17 14:37:57,201 CRITICAL uncaught exception:

Traceback (most recent call last):
  File "D:\00 eigene Daten\000 FH\S 4\Regelungstechnik\Regelungsversuch\microRay\gui\plotWidget.py", line 300, in updatePlots
    self.updateValueLabels()
  File "D:\00 eigene Daten\000 FH\S 4\Regelungstechnik\Regelungsversuch\microRay\gui\plotWidget.py", line 347, in updateValueLabels
    xData, yData = firstCurve.getData()
AttributeError: 'NoneType' object has no attribute 'getData'

2018-02-17 14:37:57,227 ERROR    uncaught exception
2018-02-17 14:37:57,227 ERROR    
2018-02-17 14:37:57,249 CRITICAL uncaught exception:

Traceback (most recent call last):
  File "D:\00 eigene Daten\000 FH\S 4\Regelungstechnik\Regelungsversuch\microRay\gui\plotWidget.py", line 300, in updatePlots
    self.updateValueLabels()
  File "D:\00 eigene Daten\000 FH\S 4\Regelungstechnik\Regelungsversuch\microRay\gui\plotWidget.py", line 347, in updateValueLabels
    xData, yData = firstCurve.getData()
AttributeError: 'NoneType' object has no attribute 'getData'

2018-02-17 14:37:57,275 ERROR    uncaught exception
2018-02-17 14:37:57,275 ERROR    
2018-02-17 14:37:57,299 CRITICAL uncaught exception:

Traceback (most recent call last):
  File "D:\00 eigene Daten\000 FH\S 4\Regelungstechnik\Regelungsversuch\microRay\gui\plotWidget.py", line 300, in updatePlots
    self.updateValueLabels()
  File "D:\00 eigene Daten\000 FH\S 4\Regelungstechnik\Regelungsversuch\microRay\gui\plotWidget.py", line 347, in updateValueLabels
    xData, yData = firstCurve.getData()
AttributeError: 'NoneType' object has no attribute 'getData'

2018-02-17 14:37:57,325 ERROR    uncaught exception
2018-02-17 14:37:57,325 ERROR    
2018-02-17 14:37:57,345 CRITICAL uncaught exception:

Traceback (most recent call last):
  File "D:\00 eigene Daten\000 FH\S 4\Regelungstechnik\Regelungsversuch\microRay\gui\plotWidget.py", line 300, in updatePlots
    self.updateValueLabels()
  File "D:\00 eigene Daten\000 FH\S 4\Regelungstechnik\Regelungsversuch\microRay\gui\plotWidget.py", line 347, in updateValueLabels
    xData, yData = firstCurve.getData()
AttributeError: 'NoneType' object has no attribute 'getData'

2018-02-17 14:37:57,369 ERROR    uncaught exception
2018-02-17 14:37:57,371 ERROR    
2018-02-17 14:37:57,391 CRITICAL uncaught exception:

Traceback (most recent call last):
  File "D:\00 eigene Daten\000 FH\S 4\Regelungstechnik\Regelungsversuch\microRay\gui\plotWidget.py", line 300, in updatePlots
    self.updateValueLabels()
  File "D:\00 eigene Daten\000 FH\S 4\Regelungstechnik\Regelungsversuch\microRay\gui\plotWidget.py", line 347, in updateValueLabels
    xData, yData = firstCurve.getData()
AttributeError: 'NoneType' object has no attribute 'getData'

2018-02-17 14:37:57,417 ERROR    uncaught exception
2018-02-17 14:37:57,417 ERROR    
2018-02-17 14:37:57,436 CRITICAL uncaught exception:

Traceback (most recent call last):
  File "D:\00 eigene Daten\000 FH\S 4\Regelungstechnik\Regelungsversuch\microRay\gui\plotWidget.py", line 300, in updatePlots
    self.updateValueLabels()
  File "D:\00 eigene Daten\000 FH\S 4\Regelungstechnik\Regelungsversuch\microRay\gui\plotWidget.py", line 347, in updateValueLabels
    xData, yData = firstCurve.getData()
AttributeError: 'NoneType' object has no attribute 'getData'

2018-02-17 14:37:57,461 ERROR    uncaught exception
2018-02-17 14:37:57,461 ERROR    
2018-02-17 14:37:57,486 CRITICAL uncaught exception:

Traceback (most recent call last):
  File "D:\00 eigene Daten\000 FH\S 4\Regelungstechnik\Regelungsversuch\microRay\gui\plotWidget.py", line 300, in updatePlots
    self.updateValueLabels()
  File "D:\00 eigene Daten\000 FH\S 4\Regelungstechnik\Regelungsversuch\microRay\gui\plotWidget.py", line 347, in updateValueLabels
    xData, yData = firstCurve.getData()
AttributeError: 'NoneType' object has no attribute 'getData'

2018-02-17 14:37:57,513 ERROR    uncaught exception
2018-02-17 14:37:57,513 ERROR    
2018-02-17 14:37:57,536 CRITICAL uncaught exception:

Traceback (most recent call last):
  File "D:\00 eigene Daten\000 FH\S 4\Regelungstechnik\Regelungsversuch\microRay\gui\plotWidget.py", line 300, in updatePlots
    self.updateValueLabels()
  File "D:\00 eigene Daten\000 FH\S 4\Regelungstechnik\Regelungsversuch\microRay\gui\plotWidget.py", line 347, in updateValueLabels
    xData, yData = firstCurve.getData()
AttributeError: 'NoneType' object has no attribute 'getData'

2018-02-17 14:37:57,561 ERROR    uncaught exception
2018-02-17 14:37:57,561 ERROR    
2018-02-17 14:37:57,581 CRITICAL uncaught exception:

Traceback (most recent call last):
  File "D:\00 eigene Daten\000 FH\S 4\Regelungstechnik\Regelungsversuch\microRay\gui\plotWidget.py", line 300, in updatePlots
    self.updateValueLabels()
  File "D:\00 eigene Daten\000 FH\S 4\Regelungstechnik\Regelungsversuch\microRay\gui\plotWidget.py", line 347, in updateValueLabels
    xData, yData = firstCurve.getData()
AttributeError: 'NoneType' object has no attribute 'getData'

2018-02-17 14:37:57,607 ERROR    uncaught exception
2018-02-17 14:37:57,608 ERROR    
2018-02-17 14:37:57,621 CRITICAL uncaught exception:

Traceback (most recent call last):
  File "D:\00 eigene Daten\000 FH\S 4\Regelungstechnik\Regelungsversuch\microRay\gui\plotWidget.py", line 300, in updatePlots
    self.updateValueLabels()
  File "D:\00 eigene Daten\000 FH\S 4\Regelungstechnik\Regelungsversuch\microRay\gui\plotWidget.py", line 347, in updateValueLabels
    xData, yData = firstCurve.getData()
AttributeError: 'NoneType' object has no attribute 'getData'

2018-02-17 14:37:57,647 ERROR    uncaught exception
2018-02-17 14:37:57,647 ERROR    
2018-02-17 14:37:57,671 CRITICAL uncaught exception:

Traceback (most recent call last):
  File "D:\00 eigene Daten\000 FH\S 4\Regelungstechnik\Regelungsversuch\microRay\gui\plotWidget.py", line 300, in updatePlots
    self.updateValueLabels()
  File "D:\00 eigene Daten\000 FH\S 4\Regelungstechnik\Regelungsversuch\microRay\gui\plotWidget.py", line 347, in updateValueLabels
    xData, yData = firstCurve.getData()
AttributeError: 'NoneType' object has no attribute 'getData'

2018-02-17 14:37:57,696 ERROR    uncaught exception
2018-02-17 14:37:57,697 ERROR    
2018-02-17 14:37:57,720 CRITICAL uncaught exception:

Traceback (most recent call last):
  File "D:\00 eigene Daten\000 FH\S 4\Regelungstechnik\Regelungsversuch\microRay\gui\plotWidget.py", line 300, in updatePlots
    self.updateValueLabels()
  File "D:\00 eigene Daten\000 FH\S 4\Regelungstechnik\Regelungsversuch\microRay\gui\plotWidget.py", line 347, in updateValueLabels
    xData, yData = firstCurve.getData()
AttributeError: 'NoneType' object has no attribute 'getData'

2018-02-17 14:37:57,746 ERROR    uncaught exception
2018-02-17 14:37:57,746 ERROR    
2018-02-17 14:37:57,769 CRITICAL uncaught exception:

Traceback (most recent call last):
  File "D:\00 eigene Daten\000 FH\S 4\Regelungstechnik\Regelungsversuch\microRay\gui\plotWidget.py", line 300, in updatePlots
    self.updateValueLabels()
  File "D:\00 eigene Daten\000 FH\S 4\Regelungstechnik\Regelungsversuch\microRay\gui\plotWidget.py", line 347, in updateValueLabels
    xData, yData = firstCurve.getData()
AttributeError: 'NoneType' object has no attribute 'getData'

2018-02-17 14:37:57,796 ERROR    uncaught exception
2018-02-17 14:37:57,798 ERROR    
2018-02-17 14:37:57,816 CRITICAL uncaught exception:

Traceback (most recent call last):
  File "D:\00 eigene Daten\000 FH\S 4\Regelungstechnik\Regelungsversuch\microRay\gui\plotWidget.py", line 300, in updatePlots
    self.updateValueLabels()
  File "D:\00 eigene Daten\000 FH\S 4\Regelungstechnik\Regelungsversuch\microRay\gui\plotWidget.py", line 347, in updateValueLabels
    xData, yData = firstCurve.getData()
AttributeError: 'NoneType' object has no attribute 'getData'

2018-02-17 14:37:57,842 ERROR    uncaught exception
2018-02-17 14:37:57,842 ERROR    
2018-02-17 14:37:57,855 CRITICAL uncaught exception:

Traceback (most recent call last):
  File "D:\00 eigene Daten\000 FH\S 4\Regelungstechnik\Regelungsversuch\microRay\gui\plotWidget.py", line 300, in updatePlots
    self.updateValueLabels()
  File "D:\00 eigene Daten\000 FH\S 4\Regelungstechnik\Regelungsversuch\microRay\gui\plotWidget.py", line 347, in updateValueLabels
    xData, yData = firstCurve.getData()
AttributeError: 'NoneType' object has no attribute 'getData'

2018-02-17 14:37:57,881 ERROR    uncaught exception
2018-02-17 14:37:57,881 ERROR    
2018-02-17 14:37:57,904 CRITICAL uncaught exception:

Traceback (most recent call last):
  File "D:\00 eigene Daten\000 FH\S 4\Regelungstechnik\Regelungsversuch\microRay\gui\plotWidget.py", line 300, in updatePlots
    self.updateValueLabels()
  File "D:\00 eigene Daten\000 FH\S 4\Regelungstechnik\Regelungsversuch\microRay\gui\plotWidget.py", line 347, in updateValueLabels
    xData, yData = firstCurve.getData()
AttributeError: 'NoneType' object has no attribute 'getData'

2018-02-17 14:37:57,930 ERROR    uncaught exception
2018-02-17 14:37:57,930 ERROR    
2018-02-17 14:37:57,950 CRITICAL uncaught exception:

Traceback (most recent call last):
  File "D:\00 eigene Daten\000 FH\S 4\Regelungstechnik\Regelungsversuch\microRay\gui\plotWidget.py", line 300, in updatePlots
    self.updateValueLabels()
  File "D:\00 eigene Daten\000 FH\S 4\Regelungstechnik\Regelungsversuch\microRay\gui\plotWidget.py", line 347, in updateValueLabels
    xData, yData = firstCurve.getData()
AttributeError: 'NoneType' object has no attribute 'getData'

2018-02-17 14:37:57,976 ERROR    uncaught exception
2018-02-17 14:37:57,976 ERROR    
2018-02-17 14:37:57,997 CRITICAL uncaught exception:

Traceback (most recent call last):
  File "D:\00 eigene Daten\000 FH\S 4\Regelungstechnik\Regelungsversuch\microRay\gui\plotWidget.py", line 300, in updatePlots
    self.updateValueLabels()
  File "D:\00 eigene Daten\000 FH\S 4\Regelungstechnik\Regelungsversuch\microRay\gui\plotWidget.py", line 347, in updateValueLabels
    xData, yData = firstCurve.getData()
AttributeError: 'NoneType' object has no attribute 'getData'

2018-02-17 14:37:58,023 ERROR    uncaught exception
2018-02-17 14:37:58,023 ERROR    
2018-02-17 14:37:58,043 CRITICAL uncaught exception:

Traceback (most recent call last):
  File "D:\00 eigene Daten\000 FH\S 4\Regelungstechnik\Regelungsversuch\microRay\gui\plotWidget.py", line 300, in updatePlots
    self.updateValueLabels()
  File "D:\00 eigene Daten\000 FH\S 4\Regelungstechnik\Regelungsversuch\microRay\gui\plotWidget.py", line 347, in updateValueLabels
    xData, yData = firstCurve.getData()
AttributeError: 'NoneType' object has no attribute 'getData'

2018-02-17 14:37:58,069 ERROR    uncaught exception
2018-02-17 14:37:58,069 ERROR    
2018-02-17 14:37:58,098 CRITICAL uncaught exception:

Traceback (most recent call last):
  File "D:\00 eigene Daten\000 FH\S 4\Regelungstechnik\Regelungsversuch\microRay\gui\plotWidget.py", line 300, in updatePlots
    self.updateValueLabels()
  File "D:\00 eigene Daten\000 FH\S 4\Regelungstechnik\Regelungsversuch\microRay\gui\plotWidget.py", line 347, in updateValueLabels
    xData, yData = firstCurve.getData()
AttributeError: 'NoneType' object has no attribute 'getData'

2018-02-17 14:37:58,125 ERROR    uncaught exception
2018-02-17 14:37:58,125 ERROR    
2018-02-17 14:37:58,144 CRITICAL uncaught exception:

Traceback (most recent call last):
  File "D:\00 eigene Daten\000 FH\S 4\Regelungstechnik\Regelungsversuch\microRay\gui\plotWidget.py", line 300, in updatePlots
    self.updateValueLabels()
  File "D:\00 eigene Daten\000 FH\S 4\Regelungstechnik\Regelungsversuch\microRay\gui\plotWidget.py", line 347, in updateValueLabels
    xData, yData = firstCurve.getData()
AttributeError: 'NoneType' object has no attribute 'getData'

2018-02-17 14:37:58,171 ERROR    uncaught exception
2018-02-17 14:37:58,171 ERROR    
2018-02-17 14:37:58,188 CRITICAL uncaught exception:

Traceback (most recent call last):
  File "D:\00 eigene Daten\000 FH\S 4\Regelungstechnik\Regelungsversuch\microRay\gui\plotWidget.py", line 300, in updatePlots
    self.updateValueLabels()
  File "D:\00 eigene Daten\000 FH\S 4\Regelungstechnik\Regelungsversuch\microRay\gui\plotWidget.py", line 347, in updateValueLabels
    xData, yData = firstCurve.getData()
AttributeError: 'NoneType' object has no attribute 'getData'

2018-02-17 14:37:58,213 ERROR    uncaught exception
2018-02-17 14:37:58,214 ERROR    
2018-02-17 14:37:58,234 CRITICAL uncaught exception:

Traceback (most recent call last):
  File "D:\00 eigene Daten\000 FH\S 4\Regelungstechnik\Regelungsversuch\microRay\gui\plotWidget.py", line 300, in updatePlots
    self.updateValueLabels()
  File "D:\00 eigene Daten\000 FH\S 4\Regelungstechnik\Regelungsversuch\microRay\gui\plotWidget.py", line 347, in updateValueLabels
    xData, yData = firstCurve.getData()
AttributeError: 'NoneType' object has no attribute 'getData'

2018-02-17 14:37:58,260 ERROR    uncaught exception
2018-02-17 14:37:58,260 ERROR    
2018-02-17 14:37:58,286 CRITICAL uncaught exception:

Traceback (most recent call last):
  File "D:\00 eigene Daten\000 FH\S 4\Regelungstechnik\Regelungsversuch\microRay\gui\plotWidget.py", line 300, in updatePlots
    self.updateValueLabels()
  File "D:\00 eigene Daten\000 FH\S 4\Regelungstechnik\Regelungsversuch\microRay\gui\plotWidget.py", line 347, in updateValueLabels
    xData, yData = firstCurve.getData()
AttributeError: 'NoneType' object has no attribute 'getData'

2018-02-17 14:37:58,311 ERROR    uncaught exception
2018-02-17 14:37:58,311 ERROR    
2018-02-17 14:37:58,332 CRITICAL uncaught exception:

Traceback (most recent call last):
  File "D:\00 eigene Daten\000 FH\S 4\Regelungstechnik\Regelungsversuch\microRay\gui\plotWidget.py", line 300, in updatePlots
    self.updateValueLabels()
  File "D:\00 eigene Daten\000 FH\S 4\Regelungstechnik\Regelungsversuch\microRay\gui\plotWidget.py", line 347, in updateValueLabels
    xData, yData = firstCurve.getData()
AttributeError: 'NoneType' object has no attribute 'getData'

2018-02-17 14:37:58,361 ERROR    uncaught exception
2018-02-17 14:37:58,361 ERROR    
2018-02-17 14:37:58,371 CRITICAL uncaught exception:

Traceback (most recent call last):
  File "D:\00 eigene Daten\000 FH\S 4\Regelungstechnik\Regelungsversuch\microRay\gui\plotWidget.py", line 300, in updatePlots
    self.updateValueLabels()
  File "D:\00 eigene Daten\000 FH\S 4\Regelungstechnik\Regelungsversuch\microRay\gui\plotWidget.py", line 347, in updateValueLabels
    xData, yData = firstCurve.getData()
AttributeError: 'NoneType' object has no attribute 'getData'

2018-02-17 14:37:58,398 ERROR    uncaught exception
2018-02-17 14:37:58,398 ERROR    
2018-02-17 14:37:58,421 CRITICAL uncaught exception:

Traceback (most recent call last):
  File "D:\00 eigene Daten\000 FH\S 4\Regelungstechnik\Regelungsversuch\microRay\gui\plotWidget.py", line 300, in updatePlots
    self.updateValueLabels()
  File "D:\00 eigene Daten\000 FH\S 4\Regelungstechnik\Regelungsversuch\microRay\gui\plotWidget.py", line 347, in updateValueLabels
    xData, yData = firstCurve.getData()
AttributeError: 'NoneType' object has no attribute 'getData'

2018-02-17 14:37:58,447 ERROR    uncaught exception
2018-02-17 14:37:58,447 ERROR    
2018-02-17 14:37:58,469 CRITICAL uncaught exception:

Traceback (most recent call last):
  File "D:\00 eigene Daten\000 FH\S 4\Regelungstechnik\Regelungsversuch\microRay\gui\plotWidget.py", line 300, in updatePlots
    self.updateValueLabels()
  File "D:\00 eigene Daten\000 FH\S 4\Regelungstechnik\Regelungsversuch\microRay\gui\plotWidget.py", line 347, in updateValueLabels
    xData, yData = firstCurve.getData()
AttributeError: 'NoneType' object has no attribute 'getData'

2018-02-17 14:37:58,494 ERROR    uncaught exception
2018-02-17 14:37:58,494 ERROR    
2018-02-17 14:37:58,519 CRITICAL uncaught exception:

Traceback (most recent call last):
  File "D:\00 eigene Daten\000 FH\S 4\Regelungstechnik\Regelungsversuch\microRay\gui\plotWidget.py", line 300, in updatePlots
    self.updateValueLabels()
  File "D:\00 eigene Daten\000 FH\S 4\Regelungstechnik\Regelungsversuch\microRay\gui\plotWidget.py", line 347, in updateValueLabels
    xData, yData = firstCurve.getData()
AttributeError: 'NoneType' object has no attribute 'getData'

2018-02-17 14:37:58,543 ERROR    uncaught exception
2018-02-17 14:37:58,543 ERROR    
2018-02-17 14:37:58,565 CRITICAL uncaught exception:

Traceback (most recent call last):
  File "D:\00 eigene Daten\000 FH\S 4\Regelungstechnik\Regelungsversuch\microRay\gui\plotWidget.py", line 300, in updatePlots
    self.updateValueLabels()
  File "D:\00 eigene Daten\000 FH\S 4\Regelungstechnik\Regelungsversuch\microRay\gui\plotWidget.py", line 347, in updateValueLabels
    xData, yData = firstCurve.getData()
AttributeError: 'NoneType' object has no attribute 'getData'

2018-02-17 14:37:58,591 ERROR    uncaught exception
2018-02-17 14:37:58,591 ERROR    
2018-02-17 14:37:58,608 CRITICAL uncaught exception:

Traceback (most recent call last):
  File "D:\00 eigene Daten\000 FH\S 4\Regelungstechnik\Regelungsversuch\microRay\gui\plotWidget.py", line 300, in updatePlots
    self.updateValueLabels()
  File "D:\00 eigene Daten\000 FH\S 4\Regelungstechnik\Regelungsversuch\microRay\gui\plotWidget.py", line 347, in updateValueLabels
    xData, yData = firstCurve.getData()
AttributeError: 'NoneType' object has no attribute 'getData'

2018-02-17 14:37:58,637 ERROR    uncaught exception
2018-02-17 14:37:58,637 ERROR    
2018-02-17 14:37:58,654 CRITICAL uncaught exception:

Traceback (most recent call last):
  File "D:\00 eigene Daten\000 FH\S 4\Regelungstechnik\Regelungsversuch\microRay\gui\plotWidget.py", line 300, in updatePlots
    self.updateValueLabels()
  File "D:\00 eigene Daten\000 FH\S 4\Regelungstechnik\Regelungsversuch\microRay\gui\plotWidget.py", line 347, in updateValueLabels
    xData, yData = firstCurve.getData()
AttributeError: 'NoneType' object has no attribute 'getData'

2018-02-17 14:37:58,680 ERROR    uncaught exception
2018-02-17 14:37:58,680 ERROR    
2018-02-17 14:37:58,706 CRITICAL uncaught exception:

Traceback (most recent call last):
  File "D:\00 eigene Daten\000 FH\S 4\Regelungstechnik\Regelungsversuch\microRay\gui\plotWidget.py", line 300, in updatePlots
    self.updateValueLabels()
  File "D:\00 eigene Daten\000 FH\S 4\Regelungstechnik\Regelungsversuch\microRay\gui\plotWidget.py", line 347, in updateValueLabels
    xData, yData = firstCurve.getData()
AttributeError: 'NoneType' object has no attribute 'getData'

2018-02-17 14:37:58,732 ERROR    uncaught exception
2018-02-17 14:37:58,732 ERROR    
2018-02-17 14:37:58,756 CRITICAL uncaught exception:

Traceback (most recent call last):
  File "D:\00 eigene Daten\000 FH\S 4\Regelungstechnik\Regelungsversuch\microRay\gui\plotWidget.py", line 300, in updatePlots
    self.updateValueLabels()
  File "D:\00 eigene Daten\000 FH\S 4\Regelungstechnik\Regelungsversuch\microRay\gui\plotWidget.py", line 347, in updateValueLabels
    xData, yData = firstCurve.getData()
AttributeError: 'NoneType' object has no attribute 'getData'

2018-02-17 14:37:58,801 ERROR    uncaught exception
2018-02-17 14:37:58,801 ERROR    
2018-02-17 14:37:58,844 CRITICAL uncaught exception:

Traceback (most recent call last):
  File "D:\00 eigene Daten\000 FH\S 4\Regelungstechnik\Regelungsversuch\microRay\gui\plotWidget.py", line 300, in updatePlots
    self.updateValueLabels()
  File "D:\00 eigene Daten\000 FH\S 4\Regelungstechnik\Regelungsversuch\microRay\gui\plotWidget.py", line 347, in updateValueLabels
    xData, yData = firstCurve.getData()
AttributeError: 'NoneType' object has no attribute 'getData'

2018-02-17 14:37:58,868 ERROR    uncaught exception
2018-02-17 14:37:58,869 ERROR    
2018-02-17 14:37:58,894 CRITICAL uncaught exception:

Traceback (most recent call last):
  File "D:\00 eigene Daten\000 FH\S 4\Regelungstechnik\Regelungsversuch\microRay\gui\plotWidget.py", line 300, in updatePlots
    self.updateValueLabels()
  File "D:\00 eigene Daten\000 FH\S 4\Regelungstechnik\Regelungsversuch\microRay\gui\plotWidget.py", line 347, in updateValueLabels
    xData, yData = firstCurve.getData()
AttributeError: 'NoneType' object has no attribute 'getData'

2018-02-17 14:37:58,921 ERROR    uncaught exception
2018-02-17 14:37:58,921 ERROR    
2018-02-17 14:37:58,937 CRITICAL uncaught exception:

Traceback (most recent call last):
  File "D:\00 eigene Daten\000 FH\S 4\Regelungstechnik\Regelungsversuch\microRay\gui\plotWidget.py", line 300, in updatePlots
    self.updateValueLabels()
  File "D:\00 eigene Daten\000 FH\S 4\Regelungstechnik\Regelungsversuch\microRay\gui\plotWidget.py", line 347, in updateValueLabels
    xData, yData = firstCurve.getData()
AttributeError: 'NoneType' object has no attribute 'getData'

2018-02-17 14:37:58,963 ERROR    uncaught exception
2018-02-17 14:37:58,963 ERROR    
2018-02-17 14:37:58,980 CRITICAL uncaught exception:

Traceback (most recent call last):
  File "D:\00 eigene Daten\000 FH\S 4\Regelungstechnik\Regelungsversuch\microRay\gui\plotWidget.py", line 300, in updatePlots
    self.updateValueLabels()
  File "D:\00 eigene Daten\000 FH\S 4\Regelungstechnik\Regelungsversuch\microRay\gui\plotWidget.py", line 347, in updateValueLabels
    xData, yData = firstCurve.getData()
AttributeError: 'NoneType' object has no attribute 'getData'

2018-02-17 14:37:59,006 ERROR    uncaught exception
2018-02-17 14:37:59,006 ERROR    
2018-02-17 14:37:59,036 CRITICAL uncaught exception:

Traceback (most recent call last):
  File "D:\00 eigene Daten\000 FH\S 4\Regelungstechnik\Regelungsversuch\microRay\gui\plotWidget.py", line 300, in updatePlots
    self.updateValueLabels()
  File "D:\00 eigene Daten\000 FH\S 4\Regelungstechnik\Regelungsversuch\microRay\gui\plotWidget.py", line 347, in updateValueLabels
    xData, yData = firstCurve.getData()
AttributeError: 'NoneType' object has no attribute 'getData'

2018-02-17 14:37:59,078 ERROR    uncaught exception
2018-02-17 14:37:59,078 ERROR    
2018-02-17 14:37:59,131 CRITICAL uncaught exception:

Traceback (most recent call last):
  File "D:\00 eigene Daten\000 FH\S 4\Regelungstechnik\Regelungsversuch\microRay\gui\plotWidget.py", line 300, in updatePlots
    self.updateValueLabels()
  File "D:\00 eigene Daten\000 FH\S 4\Regelungstechnik\Regelungsversuch\microRay\gui\plotWidget.py", line 347, in updateValueLabels
    xData, yData = firstCurve.getData()
AttributeError: 'NoneType' object has no attribute 'getData'

2018-02-17 14:37:59,186 ERROR    uncaught exception
2018-02-17 14:37:59,186 ERROR    
2018-02-17 14:37:59,214 CRITICAL uncaught exception:

Traceback (most recent call last):
  File "D:\00 eigene Daten\000 FH\S 4\Regelungstechnik\Regelungsversuch\microRay\gui\plotWidget.py", line 300, in updatePlots
    self.updateValueLabels()
  File "D:\00 eigene Daten\000 FH\S 4\Regelungstechnik\Regelungsversuch\microRay\gui\plotWidget.py", line 347, in updateValueLabels
    xData, yData = firstCurve.getData()
AttributeError: 'NoneType' object has no attribute 'getData'

2018-02-17 14:37:59,240 ERROR    uncaught exception
2018-02-17 14:37:59,240 ERROR    
2018-02-17 14:37:59,265 CRITICAL uncaught exception:

Traceback (most recent call last):
  File "D:\00 eigene Daten\000 FH\S 4\Regelungstechnik\Regelungsversuch\microRay\gui\plotWidget.py", line 300, in updatePlots
    self.updateValueLabels()
  File "D:\00 eigene Daten\000 FH\S 4\Regelungstechnik\Regelungsversuch\microRay\gui\plotWidget.py", line 347, in updateValueLabels
    xData, yData = firstCurve.getData()
AttributeError: 'NoneType' object has no attribute 'getData'

2018-02-17 14:37:59,292 ERROR    uncaught exception
2018-02-17 14:37:59,292 ERROR    
2018-02-17 14:37:59,309 CRITICAL uncaught exception:

Traceback (most recent call last):
  File "D:\00 eigene Daten\000 FH\S 4\Regelungstechnik\Regelungsversuch\microRay\gui\plotWidget.py", line 300, in updatePlots
    self.updateValueLabels()
  File "D:\00 eigene Daten\000 FH\S 4\Regelungstechnik\Regelungsversuch\microRay\gui\plotWidget.py", line 347, in updateValueLabels
    xData, yData = firstCurve.getData()
AttributeError: 'NoneType' object has no attribute 'getData'

2018-02-17 14:37:59,335 ERROR    uncaught exception
2018-02-17 14:37:59,336 ERROR    
2018-02-17 14:37:59,388 CRITICAL uncaught exception:

Traceback (most recent call last):
  File "D:\00 eigene Daten\000 FH\S 4\Regelungstechnik\Regelungsversuch\microRay\gui\plotWidget.py", line 300, in updatePlots
    self.updateValueLabels()
  File "D:\00 eigene Daten\000 FH\S 4\Regelungstechnik\Regelungsversuch\microRay\gui\plotWidget.py", line 347, in updateValueLabels
    xData, yData = firstCurve.getData()
AttributeError: 'NoneType' object has no attribute 'getData'

2018-02-17 14:37:59,413 ERROR    uncaught exception
2018-02-17 14:37:59,414 ERROR    
2018-02-17 14:37:59,457 CRITICAL uncaught exception:

Traceback (most recent call last):
  File "D:\00 eigene Daten\000 FH\S 4\Regelungstechnik\Regelungsversuch\microRay\gui\plotWidget.py", line 300, in updatePlots
    self.updateValueLabels()
  File "D:\00 eigene Daten\000 FH\S 4\Regelungstechnik\Regelungsversuch\microRay\gui\plotWidget.py", line 347, in updateValueLabels
    xData, yData = firstCurve.getData()
AttributeError: 'NoneType' object has no attribute 'getData'

2018-02-17 14:37:59,483 ERROR    uncaught exception
2018-02-17 14:37:59,483 ERROR    
2018-02-17 14:37:59,496 CRITICAL uncaught exception:

Traceback (most recent call last):
  File "D:\00 eigene Daten\000 FH\S 4\Regelungstechnik\Regelungsversuch\microRay\gui\plotWidget.py", line 300, in updatePlots
    self.updateValueLabels()
  File "D:\00 eigene Daten\000 FH\S 4\Regelungstechnik\Regelungsversuch\microRay\gui\plotWidget.py", line 347, in updateValueLabels
    xData, yData = firstCurve.getData()
AttributeError: 'NoneType' object has no attribute 'getData'

2018-02-17 14:37:59,523 ERROR    uncaught exception
2018-02-17 14:37:59,523 ERROR    
2018-02-17 14:37:59,546 CRITICAL uncaught exception:

Traceback (most recent call last):
  File "D:\00 eigene Daten\000 FH\S 4\Regelungstechnik\Regelungsversuch\microRay\gui\plotWidget.py", line 300, in updatePlots
    self.updateValueLabels()
  File "D:\00 eigene Daten\000 FH\S 4\Regelungstechnik\Regelungsversuch\microRay\gui\plotWidget.py", line 347, in updateValueLabels
    xData, yData = firstCurve.getData()
AttributeError: 'NoneType' object has no attribute 'getData'

2018-02-17 14:37:59,571 ERROR    uncaught exception
2018-02-17 14:37:59,572 ERROR    
2018-02-17 14:37:59,596 CRITICAL uncaught exception:

Traceback (most recent call last):
  File "D:\00 eigene Daten\000 FH\S 4\Regelungstechnik\Regelungsversuch\microRay\gui\plotWidget.py", line 300, in updatePlots
    self.updateValueLabels()
  File "D:\00 eigene Daten\000 FH\S 4\Regelungstechnik\Regelungsversuch\microRay\gui\plotWidget.py", line 347, in updateValueLabels
    xData, yData = firstCurve.getData()
AttributeError: 'NoneType' object has no attribute 'getData'

2018-02-17 14:37:59,621 ERROR    uncaught exception
2018-02-17 14:37:59,622 ERROR    
2018-02-17 14:37:59,641 CRITICAL uncaught exception:

Traceback (most recent call last):
  File "D:\00 eigene Daten\000 FH\S 4\Regelungstechnik\Regelungsversuch\microRay\gui\plotWidget.py", line 300, in updatePlots
    self.updateValueLabels()
  File "D:\00 eigene Daten\000 FH\S 4\Regelungstechnik\Regelungsversuch\microRay\gui\plotWidget.py", line 347, in updateValueLabels
    xData, yData = firstCurve.getData()
AttributeError: 'NoneType' object has no attribute 'getData'

2018-02-17 14:37:59,667 ERROR    uncaught exception
2018-02-17 14:37:59,667 ERROR    
2018-02-17 14:37:59,684 CRITICAL uncaught exception:

Traceback (most recent call last):
  File "D:\00 eigene Daten\000 FH\S 4\Regelungstechnik\Regelungsversuch\microRay\gui\plotWidget.py", line 300, in updatePlots
    self.updateValueLabels()
  File "D:\00 eigene Daten\000 FH\S 4\Regelungstechnik\Regelungsversuch\microRay\gui\plotWidget.py", line 347, in updateValueLabels
    xData, yData = firstCurve.getData()
AttributeError: 'NoneType' object has no attribute 'getData'

2018-02-17 14:37:59,710 ERROR    uncaught exception
2018-02-17 14:37:59,710 ERROR    
2018-02-17 14:37:59,736 CRITICAL uncaught exception:

Traceback (most recent call last):
  File "D:\00 eigene Daten\000 FH\S 4\Regelungstechnik\Regelungsversuch\microRay\gui\plotWidget.py", line 300, in updatePlots
    self.updateValueLabels()
  File "D:\00 eigene Daten\000 FH\S 4\Regelungstechnik\Regelungsversuch\microRay\gui\plotWidget.py", line 347, in updateValueLabels
    xData, yData = firstCurve.getData()
AttributeError: 'NoneType' object has no attribute 'getData'

2018-02-17 14:37:59,760 ERROR    uncaught exception
2018-02-17 14:37:59,762 ERROR    
2018-02-17 14:37:59,786 CRITICAL uncaught exception:

Traceback (most recent call last):
  File "D:\00 eigene Daten\000 FH\S 4\Regelungstechnik\Regelungsversuch\microRay\gui\plotWidget.py", line 300, in updatePlots
    self.updateValueLabels()
  File "D:\00 eigene Daten\000 FH\S 4\Regelungstechnik\Regelungsversuch\microRay\gui\plotWidget.py", line 347, in updateValueLabels
    xData, yData = firstCurve.getData()
AttributeError: 'NoneType' object has no attribute 'getData'

2018-02-17 14:37:59,811 ERROR    uncaught exception
2018-02-17 14:37:59,811 ERROR    
2018-02-17 14:37:59,831 CRITICAL uncaught exception:

Traceback (most recent call last):
  File "D:\00 eigene Daten\000 FH\S 4\Regelungstechnik\Regelungsversuch\microRay\gui\plotWidget.py", line 300, in updatePlots
    self.updateValueLabels()
  File "D:\00 eigene Daten\000 FH\S 4\Regelungstechnik\Regelungsversuch\microRay\gui\plotWidget.py", line 347, in updateValueLabels
    xData, yData = firstCurve.getData()
AttributeError: 'NoneType' object has no attribute 'getData'

2018-02-17 14:37:59,855 ERROR    uncaught exception
2018-02-17 14:37:59,855 ERROR    
2018-02-17 14:37:59,871 CRITICAL uncaught exception:

Traceback (most recent call last):
  File "D:\00 eigene Daten\000 FH\S 4\Regelungstechnik\Regelungsversuch\microRay\gui\plotWidget.py", line 300, in updatePlots
    self.updateValueLabels()
  File "D:\00 eigene Daten\000 FH\S 4\Regelungstechnik\Regelungsversuch\microRay\gui\plotWidget.py", line 347, in updateValueLabels
    xData, yData = firstCurve.getData()
AttributeError: 'NoneType' object has no attribute 'getData'

2018-02-17 14:37:59,895 ERROR    uncaught exception
2018-02-17 14:37:59,897 ERROR    
2018-02-17 14:37:59,918 CRITICAL uncaught exception:

Traceback (most recent call last):
  File "D:\00 eigene Daten\000 FH\S 4\Regelungstechnik\Regelungsversuch\microRay\gui\plotWidget.py", line 300, in updatePlots
    self.updateValueLabels()
  File "D:\00 eigene Daten\000 FH\S 4\Regelungstechnik\Regelungsversuch\microRay\gui\plotWidget.py", line 347, in updateValueLabels
    xData, yData = firstCurve.getData()
AttributeError: 'NoneType' object has no attribute 'getData'

2018-02-17 14:37:59,944 ERROR    uncaught exception
2018-02-17 14:37:59,944 ERROR    
2018-02-17 14:37:59,966 CRITICAL uncaught exception:

Traceback (most recent call last):
  File "D:\00 eigene Daten\000 FH\S 4\Regelungstechnik\Regelungsversuch\microRay\gui\plotWidget.py", line 300, in updatePlots
    self.updateValueLabels()
  File "D:\00 eigene Daten\000 FH\S 4\Regelungstechnik\Regelungsversuch\microRay\gui\plotWidget.py", line 347, in updateValueLabels
    xData, yData = firstCurve.getData()
AttributeError: 'NoneType' object has no attribute 'getData'

2018-02-17 14:37:59,992 ERROR    uncaught exception
2018-02-17 14:37:59,992 ERROR    
2018-02-17 14:38:00,016 CRITICAL uncaught exception:

Traceback (most recent call last):
  File "D:\00 eigene Daten\000 FH\S 4\Regelungstechnik\Regelungsversuch\microRay\gui\plotWidget.py", line 300, in updatePlots
    self.updateValueLabels()
  File "D:\00 eigene Daten\000 FH\S 4\Regelungstechnik\Regelungsversuch\microRay\gui\plotWidget.py", line 347, in updateValueLabels
    xData, yData = firstCurve.getData()
AttributeError: 'NoneType' object has no attribute 'getData'

2018-02-17 14:38:00,042 ERROR    uncaught exception
2018-02-17 14:38:00,042 ERROR    
2018-02-17 14:38:00,059 CRITICAL uncaught exception:

Traceback (most recent call last):
  File "D:\00 eigene Daten\000 FH\S 4\Regelungstechnik\Regelungsversuch\microRay\gui\plotWidget.py", line 300, in updatePlots
    self.updateValueLabels()
  File "D:\00 eigene Daten\000 FH\S 4\Regelungstechnik\Regelungsversuch\microRay\gui\plotWidget.py", line 347, in updateValueLabels
    xData, yData = firstCurve.getData()
AttributeError: 'NoneType' object has no attribute 'getData'

2018-02-17 14:38:00,085 ERROR    uncaught exception
2018-02-17 14:38:00,085 ERROR    
2018-02-17 14:38:00,107 CRITICAL uncaught exception:

Traceback (most recent call last):
  File "D:\00 eigene Daten\000 FH\S 4\Regelungstechnik\Regelungsversuch\microRay\gui\plotWidget.py", line 300, in updatePlots
    self.updateValueLabels()
  File "D:\00 eigene Daten\000 FH\S 4\Regelungstechnik\Regelungsversuch\microRay\gui\plotWidget.py", line 347, in updateValueLabels
    xData, yData = firstCurve.getData()
AttributeError: 'NoneType' object has no attribute 'getData'

2018-02-17 14:38:00,134 ERROR    uncaught exception
2018-02-17 14:38:00,134 ERROR    
2018-02-17 14:38:00,154 CRITICAL uncaught exception:

Traceback (most recent call last):
  File "D:\00 eigene Daten\000 FH\S 4\Regelungstechnik\Regelungsversuch\microRay\gui\plotWidget.py", line 300, in updatePlots
    self.updateValueLabels()
  File "D:\00 eigene Daten\000 FH\S 4\Regelungstechnik\Regelungsversuch\microRay\gui\plotWidget.py", line 347, in updateValueLabels
    xData, yData = firstCurve.getData()
AttributeError: 'NoneType' object has no attribute 'getData'

2018-02-17 14:38:00,178 ERROR    uncaught exception
2018-02-17 14:38:00,180 ERROR    
2018-02-17 14:38:00,203 CRITICAL uncaught exception:

Traceback (most recent call last):
  File "D:\00 eigene Daten\000 FH\S 4\Regelungstechnik\Regelungsversuch\microRay\gui\plotWidget.py", line 300, in updatePlots
    self.updateValueLabels()
  File "D:\00 eigene Daten\000 FH\S 4\Regelungstechnik\Regelungsversuch\microRay\gui\plotWidget.py", line 347, in updateValueLabels
    xData, yData = firstCurve.getData()
AttributeError: 'NoneType' object has no attribute 'getData'

2018-02-17 14:38:00,229 ERROR    uncaught exception
2018-02-17 14:38:00,229 ERROR    
2018-02-17 14:38:00,249 CRITICAL uncaught exception:

Traceback (most recent call last):
  File "D:\00 eigene Daten\000 FH\S 4\Regelungstechnik\Regelungsversuch\microRay\gui\plotWidget.py", line 300, in updatePlots
    self.updateValueLabels()
  File "D:\00 eigene Daten\000 FH\S 4\Regelungstechnik\Regelungsversuch\microRay\gui\plotWidget.py", line 347, in updateValueLabels
    xData, yData = firstCurve.getData()
AttributeError: 'NoneType' object has no attribute 'getData'

2018-02-17 14:38:00,275 ERROR    uncaught exception
2018-02-17 14:38:00,275 ERROR    
2018-02-17 14:38:00,293 CRITICAL uncaught exception:

Traceback (most recent call last):
  File "D:\00 eigene Daten\000 FH\S 4\Regelungstechnik\Regelungsversuch\microRay\gui\plotWidget.py", line 300, in updatePlots
    self.updateValueLabels()
  File "D:\00 eigene Daten\000 FH\S 4\Regelungstechnik\Regelungsversuch\microRay\gui\plotWidget.py", line 347, in updateValueLabels
    xData, yData = firstCurve.getData()
AttributeError: 'NoneType' object has no attribute 'getData'

2018-02-17 14:38:00,319 ERROR    uncaught exception
2018-02-17 14:38:00,319 ERROR    
2018-02-17 14:38:00,342 CRITICAL uncaught exception:

Traceback (most recent call last):
  File "D:\00 eigene Daten\000 FH\S 4\Regelungstechnik\Regelungsversuch\microRay\gui\plotWidget.py", line 300, in updatePlots
    self.updateValueLabels()
  File "D:\00 eigene Daten\000 FH\S 4\Regelungstechnik\Regelungsversuch\microRay\gui\plotWidget.py", line 347, in updateValueLabels
    xData, yData = firstCurve.getData()
AttributeError: 'NoneType' object has no attribute 'getData'

2018-02-17 14:38:00,368 ERROR    uncaught exception
2018-02-17 14:38:00,368 ERROR    
2018-02-17 14:38:00,390 CRITICAL uncaught exception:

Traceback (most recent call last):
  File "D:\00 eigene Daten\000 FH\S 4\Regelungstechnik\Regelungsversuch\microRay\gui\plotWidget.py", line 300, in updatePlots
    self.updateValueLabels()
  File "D:\00 eigene Daten\000 FH\S 4\Regelungstechnik\Regelungsversuch\microRay\gui\plotWidget.py", line 347, in updateValueLabels
    xData, yData = firstCurve.getData()
AttributeError: 'NoneType' object has no attribute 'getData'

2018-02-17 14:38:00,414 ERROR    uncaught exception
2018-02-17 14:38:00,415 ERROR    
2018-02-17 14:38:00,434 CRITICAL uncaught exception:

Traceback (most recent call last):
  File "D:\00 eigene Daten\000 FH\S 4\Regelungstechnik\Regelungsversuch\microRay\gui\plotWidget.py", line 300, in updatePlots
    self.updateValueLabels()
  File "D:\00 eigene Daten\000 FH\S 4\Regelungstechnik\Regelungsversuch\microRay\gui\plotWidget.py", line 347, in updateValueLabels
    xData, yData = firstCurve.getData()
AttributeError: 'NoneType' object has no attribute 'getData'

2018-02-17 14:38:00,460 ERROR    uncaught exception
2018-02-17 14:38:00,460 ERROR    
2018-02-17 14:38:00,483 CRITICAL uncaught exception:

Traceback (most recent call last):
  File "D:\00 eigene Daten\000 FH\S 4\Regelungstechnik\Regelungsversuch\microRay\gui\plotWidget.py", line 300, in updatePlots
    self.updateValueLabels()
  File "D:\00 eigene Daten\000 FH\S 4\Regelungstechnik\Regelungsversuch\microRay\gui\plotWidget.py", line 347, in updateValueLabels
    xData, yData = firstCurve.getData()
AttributeError: 'NoneType' object has no attribute 'getData'

2018-02-17 14:38:00,510 ERROR    uncaught exception
2018-02-17 14:38:00,510 ERROR    
2018-02-17 14:38:00,529 CRITICAL uncaught exception:

Traceback (most recent call last):
  File "D:\00 eigene Daten\000 FH\S 4\Regelungstechnik\Regelungsversuch\microRay\gui\plotWidget.py", line 300, in updatePlots
    self.updateValueLabels()
  File "D:\00 eigene Daten\000 FH\S 4\Regelungstechnik\Regelungsversuch\microRay\gui\plotWidget.py", line 347, in updateValueLabels
    xData, yData = firstCurve.getData()
AttributeError: 'NoneType' object has no attribute 'getData'

2018-02-17 14:38:00,555 ERROR    uncaught exception
2018-02-17 14:38:00,555 ERROR    
2018-02-17 14:38:00,578 CRITICAL uncaught exception:

Traceback (most recent call last):
  File "D:\00 eigene Daten\000 FH\S 4\Regelungstechnik\Regelungsversuch\microRay\gui\plotWidget.py", line 300, in updatePlots
    self.updateValueLabels()
  File "D:\00 eigene Daten\000 FH\S 4\Regelungstechnik\Regelungsversuch\microRay\gui\plotWidget.py", line 347, in updateValueLabels
    xData, yData = firstCurve.getData()
AttributeError: 'NoneType' object has no attribute 'getData'

2018-02-17 14:38:00,605 ERROR    uncaught exception
2018-02-17 14:38:00,605 ERROR    
2018-02-17 14:38:00,621 CRITICAL uncaught exception:

Traceback (most recent call last):
  File "D:\00 eigene Daten\000 FH\S 4\Regelungstechnik\Regelungsversuch\microRay\gui\plotWidget.py", line 300, in updatePlots
    self.updateValueLabels()
  File "D:\00 eigene Daten\000 FH\S 4\Regelungstechnik\Regelungsversuch\microRay\gui\plotWidget.py", line 347, in updateValueLabels
    xData, yData = firstCurve.getData()
AttributeError: 'NoneType' object has no attribute 'getData'

2018-02-17 14:38:00,648 ERROR    uncaught exception
2018-02-17 14:38:00,648 ERROR    
2018-02-17 14:38:00,671 CRITICAL uncaught exception:

Traceback (most recent call last):
  File "D:\00 eigene Daten\000 FH\S 4\Regelungstechnik\Regelungsversuch\microRay\gui\plotWidget.py", line 300, in updatePlots
    self.updateValueLabels()
  File "D:\00 eigene Daten\000 FH\S 4\Regelungstechnik\Regelungsversuch\microRay\gui\plotWidget.py", line 347, in updateValueLabels
    xData, yData = firstCurve.getData()
AttributeError: 'NoneType' object has no attribute 'getData'

2018-02-17 14:38:00,696 ERROR    uncaught exception
2018-02-17 14:38:00,696 ERROR    
2018-02-17 14:38:00,719 CRITICAL uncaught exception:

Traceback (most recent call last):
  File "D:\00 eigene Daten\000 FH\S 4\Regelungstechnik\Regelungsversuch\microRay\gui\plotWidget.py", line 300, in updatePlots
    self.updateValueLabels()
  File "D:\00 eigene Daten\000 FH\S 4\Regelungstechnik\Regelungsversuch\microRay\gui\plotWidget.py", line 347, in updateValueLabels
    xData, yData = firstCurve.getData()
AttributeError: 'NoneType' object has no attribute 'getData'

2018-02-17 14:38:00,743 ERROR    uncaught exception
2018-02-17 14:38:00,743 ERROR    
2018-02-17 14:38:00,769 CRITICAL uncaught exception:

Traceback (most recent call last):
  File "D:\00 eigene Daten\000 FH\S 4\Regelungstechnik\Regelungsversuch\microRay\gui\plotWidget.py", line 300, in updatePlots
    self.updateValueLabels()
  File "D:\00 eigene Daten\000 FH\S 4\Regelungstechnik\Regelungsversuch\microRay\gui\plotWidget.py", line 347, in updateValueLabels
    xData, yData = firstCurve.getData()
AttributeError: 'NoneType' object has no attribute 'getData'

2018-02-17 14:38:00,799 ERROR    uncaught exception
2018-02-17 14:38:00,799 ERROR    
2018-02-17 14:38:00,831 CRITICAL uncaught exception:

Traceback (most recent call last):
  File "D:\00 eigene Daten\000 FH\S 4\Regelungstechnik\Regelungsversuch\microRay\gui\plotWidget.py", line 300, in updatePlots
    self.updateValueLabels()
  File "D:\00 eigene Daten\000 FH\S 4\Regelungstechnik\Regelungsversuch\microRay\gui\plotWidget.py", line 347, in updateValueLabels
    xData, yData = firstCurve.getData()
AttributeError: 'NoneType' object has no attribute 'getData'

2018-02-17 14:38:00,864 ERROR    uncaught exception
2018-02-17 14:38:00,864 ERROR    
2018-02-17 14:38:00,905 CRITICAL uncaught exception:

Traceback (most recent call last):
  File "D:\00 eigene Daten\000 FH\S 4\Regelungstechnik\Regelungsversuch\microRay\gui\plotWidget.py", line 300, in updatePlots
    self.updateValueLabels()
  File "D:\00 eigene Daten\000 FH\S 4\Regelungstechnik\Regelungsversuch\microRay\gui\plotWidget.py", line 347, in updateValueLabels
    xData, yData = firstCurve.getData()
AttributeError: 'NoneType' object has no attribute 'getData'

2018-02-17 14:38:00,931 ERROR    uncaught exception
2018-02-17 14:38:00,931 ERROR    
2018-02-17 14:38:00,953 CRITICAL uncaught exception:

Traceback (most recent call last):
  File "D:\00 eigene Daten\000 FH\S 4\Regelungstechnik\Regelungsversuch\microRay\gui\plotWidget.py", line 300, in updatePlots
    self.updateValueLabels()
  File "D:\00 eigene Daten\000 FH\S 4\Regelungstechnik\Regelungsversuch\microRay\gui\plotWidget.py", line 347, in updateValueLabels
    xData, yData = firstCurve.getData()
AttributeError: 'NoneType' object has no attribute 'getData'

2018-02-17 14:38:00,982 ERROR    uncaught exception
2018-02-17 14:38:00,982 ERROR    
2018-02-17 14:38:01,000 CRITICAL uncaught exception:

Traceback (most recent call last):
  File "D:\00 eigene Daten\000 FH\S 4\Regelungstechnik\Regelungsversuch\microRay\gui\plotWidget.py", line 300, in updatePlots
    self.updateValueLabels()
  File "D:\00 eigene Daten\000 FH\S 4\Regelungstechnik\Regelungsversuch\microRay\gui\plotWidget.py", line 347, in updateValueLabels
    xData, yData = firstCurve.getData()
AttributeError: 'NoneType' object has no attribute 'getData'

2018-02-17 14:38:01,028 ERROR    uncaught exception
2018-02-17 14:38:01,028 ERROR    
2018-02-17 14:38:01,046 CRITICAL uncaught exception:

Traceback (most recent call last):
  File "D:\00 eigene Daten\000 FH\S 4\Regelungstechnik\Regelungsversuch\microRay\gui\plotWidget.py", line 300, in updatePlots
    self.updateValueLabels()
  File "D:\00 eigene Daten\000 FH\S 4\Regelungstechnik\Regelungsversuch\microRay\gui\plotWidget.py", line 347, in updateValueLabels
    xData, yData = firstCurve.getData()
AttributeError: 'NoneType' object has no attribute 'getData'

2018-02-17 14:38:01,072 ERROR    uncaught exception
2018-02-17 14:38:01,072 ERROR    
2018-02-17 14:38:01,094 CRITICAL uncaught exception:

Traceback (most recent call last):
  File "D:\00 eigene Daten\000 FH\S 4\Regelungstechnik\Regelungsversuch\microRay\gui\plotWidget.py", line 300, in updatePlots
    self.updateValueLabels()
  File "D:\00 eigene Daten\000 FH\S 4\Regelungstechnik\Regelungsversuch\microRay\gui\plotWidget.py", line 347, in updateValueLabels
    xData, yData = firstCurve.getData()
AttributeError: 'NoneType' object has no attribute 'getData'

2018-02-17 14:38:01,119 ERROR    uncaught exception
2018-02-17 14:38:01,119 ERROR    
2018-02-17 14:38:01,141 CRITICAL uncaught exception:

Traceback (most recent call last):
  File "D:\00 eigene Daten\000 FH\S 4\Regelungstechnik\Regelungsversuch\microRay\gui\plotWidget.py", line 300, in updatePlots
    self.updateValueLabels()
  File "D:\00 eigene Daten\000 FH\S 4\Regelungstechnik\Regelungsversuch\microRay\gui\plotWidget.py", line 347, in updateValueLabels
    xData, yData = firstCurve.getData()
AttributeError: 'NoneType' object has no attribute 'getData'

2018-02-17 14:38:01,167 ERROR    uncaught exception
2018-02-17 14:38:01,167 ERROR    
2018-02-17 14:38:01,187 CRITICAL uncaught exception:

Traceback (most recent call last):
  File "D:\00 eigene Daten\000 FH\S 4\Regelungstechnik\Regelungsversuch\microRay\gui\plotWidget.py", line 300, in updatePlots
    self.updateValueLabels()
  File "D:\00 eigene Daten\000 FH\S 4\Regelungstechnik\Regelungsversuch\microRay\gui\plotWidget.py", line 347, in updateValueLabels
    xData, yData = firstCurve.getData()
AttributeError: 'NoneType' object has no attribute 'getData'

2018-02-17 14:38:01,213 ERROR    uncaught exception
2018-02-17 14:38:01,213 ERROR    
2018-02-17 14:38:01,232 CRITICAL uncaught exception:

Traceback (most recent call last):
  File "D:\00 eigene Daten\000 FH\S 4\Regelungstechnik\Regelungsversuch\microRay\gui\plotWidget.py", line 300, in updatePlots
    self.updateValueLabels()
  File "D:\00 eigene Daten\000 FH\S 4\Regelungstechnik\Regelungsversuch\microRay\gui\plotWidget.py", line 347, in updateValueLabels
    xData, yData = firstCurve.getData()
AttributeError: 'NoneType' object has no attribute 'getData'

2018-02-17 14:38:01,257 ERROR    uncaught exception
2018-02-17 14:38:01,257 ERROR    
2018-02-17 14:38:01,282 CRITICAL uncaught exception:

Traceback (most recent call last):
  File "D:\00 eigene Daten\000 FH\S 4\Regelungstechnik\Regelungsversuch\microRay\gui\plotWidget.py", line 300, in updatePlots
    self.updateValueLabels()
  File "D:\00 eigene Daten\000 FH\S 4\Regelungstechnik\Regelungsversuch\microRay\gui\plotWidget.py", line 347, in updateValueLabels
    xData, yData = firstCurve.getData()
AttributeError: 'NoneType' object has no attribute 'getData'

2018-02-17 14:38:01,326 ERROR    uncaught exception
2018-02-17 14:38:01,326 ERROR    
