2018-02-17 14:38:01,377 CRITICAL uncaught exception:

Traceback (most recent call last):
  File "D:\00 eigene Daten\000 FH\S 4\Regelungstechnik\Regelungsversuch\microRay\gui\plotWidget.py", line 300, in updatePlots
    self.updateValueLabels()
  File "D:\00 eigene Daten\000 FH\S 4\Regelungstechnik\Regelungsversuch\microRay\gui\plotWidget.py", line 347, in updateValueLabels
    xData, yData = firstCurve.getData()
AttributeError: 'NoneType' object has no attribute 'getData'

2018-02-17 14:38:01,434 ERROR    uncaught exception
2018-02-17 14:38:01,436 ERROR    
2018-02-17 14:38:01,467 CRITICAL uncaught exception:

Traceback (most recent call last):
  File "D:\00 eigene Daten\000 FH\S 4\Regelungstechnik\Regelungsversuch\microRay\gui\plotWidget.py", line 300, in updatePlots
    self.updateValueLabels()
  File "D:\00 eigene Daten\000 FH\S 4\Regelungstechnik\Regelungsversuch\microRay\gui\plotWidget.py", line 347, in updateValueLabels
    xData, yData = firstCurve.getData()
AttributeError: 'NoneType' object has no attribute 'getData'

2018-02-17 14:38:01,519 ERROR    uncaught exception
2018-02-17 14:38:01,520 ERROR    
2018-02-17 14:38:01,559 CRITICAL uncaught exception:

Traceback (most recent call last):
  File "D:\00 eigene Daten\000 FH\S 4\Regelungstechnik\Regelungsversuch\microRay\gui\plotWidget.py", line 300, in updatePlots
    self.updateValueLabels()
  File "D:\00 eigene Daten\000 FH\S 4\Regelungstechnik\Regelungsversuch\microRay\gui\plotWidget.py", line 347, in updateValueLabels
    xData, yData = firstCurve.getData()
AttributeError: 'NoneType' object has no attribute 'getData'

2018-02-17 14:38:01,586 ERROR    uncaught exception
2018-02-17 14:38:01,586 ERROR    
2018-02-17 14:38:01,607 CRITICAL uncaught exception:

Traceback (most recent call last):
  File "D:\00 eigene Daten\000 FH\S 4\Regelungstechnik\Regelungsversuch\microRay\gui\plotWidget.py", line 300, in updatePlots
    self.updateValueLabels()
  File "D:\00 eigene Daten\000 FH\S 4\Regelungstechnik\Regelungsversuch\microRay\gui\plotWidget.py", line 347, in updateValueLabels
    xData, yData = firstCurve.getData()
AttributeError: 'NoneType' object has no attribute 'getData'

2018-02-17 14:38:01,631 ERROR    uncaught exception
2018-02-17 14:38:01,631 ERROR    
2018-02-17 14:38:01,654 CRITICAL uncaught exception:

Traceback (most recent call last):
  File "D:\00 eigene Daten\000 FH\S 4\Regelungstechnik\Regelungsversuch\microRay\gui\plotWidget.py", line 300, in updatePlots
    self.updateValueLabels()
  File "D:\00 eigene Daten\000 FH\S 4\Regelungstechnik\Regelungsversuch\microRay\gui\plotWidget.py", line 347, in updateValueLabels
    xData, yData = firstCurve.getData()
AttributeError: 'NoneType' object has no attribute 'getData'

2018-02-17 14:38:01,680 ERROR    uncaught exception
2018-02-17 14:38:01,680 ERROR    
2018-02-17 14:38:01,704 CRITICAL uncaught exception:

Traceback (most recent call last):
  File "D:\00 eigene Daten\000 FH\S 4\Regelungstechnik\Regelungsversuch\microRay\gui\plotWidget.py", line 300, in updatePlots
    self.updateValueLabels()
  File "D:\00 eigene Daten\000 FH\S 4\Regelungstechnik\Regelungsversuch\microRay\gui\plotWidget.py", line 347, in updateValueLabels
    xData, yData = firstCurve.getData()
AttributeError: 'NoneType' object has no attribute 'getData'

2018-02-17 14:38:01,752 ERROR    uncaught exception
2018-02-17 14:38:01,752 ERROR    
2018-02-17 14:38:01,793 CRITICAL uncaught exception:

Traceback (most recent call last):
  File "D:\00 eigene Daten\000 FH\S 4\Regelungstechnik\Regelungsversuch\microRay\gui\plotWidget.py", line 300, in updatePlots
    self.updateValueLabels()
  File "D:\00 eigene Daten\000 FH\S 4\Regelungstechnik\Regelungsversuch\microRay\gui\plotWidget.py", line 347, in updateValueLabels
    xData, yData = firstCurve.getData()
AttributeError: 'NoneType' object has no attribute 'getData'

2018-02-17 14:38:01,838 ERROR    uncaught exception
2018-02-17 14:38:01,839 ERROR    
2018-02-17 14:38:01,891 CRITICAL uncaught exception:

Traceback (most recent call last):
  File "D:\00 eigene Daten\000 FH\S 4\Regelungstechnik\Regelungsversuch\microRay\gui\plotWidget.py", line 300, in updatePlots
    self.updateValueLabels()
  File "D:\00 eigene Daten\000 FH\S 4\Regelungstechnik\Regelungsversuch\microRay\gui\plotWidget.py", line 347, in updateValueLabels
    xData, yData = firstCurve.getData()
AttributeError: 'NoneType' object has no attribute 'getData'

2018-02-17 14:38:01,924 ERROR    uncaught exception
2018-02-17 14:38:01,924 ERROR    
2018-02-17 14:38:01,936 CRITICAL uncaught exception:

Traceback (most recent call last):
  File "D:\00 eigene Daten\000 FH\S 4\Regelungstechnik\Regelungsversuch\microRay\gui\plotWidget.py", line 300, in updatePlots
    self.updateValueLabels()
  File "D:\00 eigene Daten\000 FH\S 4\Regelungstechnik\Regelungsversuch\microRay\gui\plotWidget.py", line 347, in updateValueLabels
    xData, yData = firstCurve.getData()
AttributeError: 'NoneType' object has no attribute 'getData'

2018-02-17 14:38:01,960 ERROR    uncaught exception
2018-02-17 14:38:01,960 ERROR    
2018-02-17 14:38:01,983 CRITICAL uncaught exception:

Traceback (most recent call last):
  File "D:\00 eigene Daten\000 FH\S 4\Regelungstechnik\Regelungsversuch\microRay\gui\plotWidget.py", line 300, in updatePlots
    self.updateValueLabels()
  File "D:\00 eigene Daten\000 FH\S 4\Regelungstechnik\Regelungsversuch\microRay\gui\plotWidget.py", line 347, in updateValueLabels
    xData, yData = firstCurve.getData()
AttributeError: 'NoneType' object has no attribute 'getData'

2018-02-17 14:38:02,010 ERROR    uncaught exception
2018-02-17 14:38:02,010 ERROR    
2018-02-17 14:38:02,030 CRITICAL uncaught exception:

Traceback (most recent call last):
  File "D:\00 eigene Daten\000 FH\S 4\Regelungstechnik\Regelungsversuch\microRay\gui\plotWidget.py", line 300, in updatePlots
    self.updateValueLabels()
  File "D:\00 eigene Daten\000 FH\S 4\Regelungstechnik\Regelungsversuch\microRay\gui\plotWidget.py", line 347, in updateValueLabels
    xData, yData = firstCurve.getData()
AttributeError: 'NoneType' object has no attribute 'getData'

2018-02-17 14:38:02,055 ERROR    uncaught exception
2018-02-17 14:38:02,055 ERROR    
2018-02-17 14:38:02,078 CRITICAL uncaught exception:

Traceback (most recent call last):
  File "D:\00 eigene Daten\000 FH\S 4\Regelungstechnik\Regelungsversuch\microRay\gui\plotWidget.py", line 300, in updatePlots
    self.updateValueLabels()
  File "D:\00 eigene Daten\000 FH\S 4\Regelungstechnik\Regelungsversuch\microRay\gui\plotWidget.py", line 347, in updateValueLabels
    xData, yData = firstCurve.getData()
AttributeError: 'NoneType' object has no attribute 'getData'

2018-02-17 14:38:02,105 ERROR    uncaught exception
2018-02-17 14:38:02,105 ERROR    
2018-02-17 14:38:02,125 CRITICAL uncaught exception:

Traceback (most recent call last):
  File "D:\00 eigene Daten\000 FH\S 4\Regelungstechnik\Regelungsversuch\microRay\gui\plotWidget.py", line 300, in updatePlots
    self.updateValueLabels()
  File "D:\00 eigene Daten\000 FH\S 4\Regelungstechnik\Regelungsversuch\microRay\gui\plotWidget.py", line 347, in updateValueLabels
    xData, yData = firstCurve.getData()
AttributeError: 'NoneType' object has no attribute 'getData'

2018-02-17 14:38:02,151 ERROR    uncaught exception
2018-02-17 14:38:02,151 ERROR    
2018-02-17 14:38:02,174 CRITICAL uncaught exception:

Traceback (most recent call last):
  File "D:\00 eigene Daten\000 FH\S 4\Regelungstechnik\Regelungsversuch\microRay\gui\plotWidget.py", line 300, in updatePlots
    self.updateValueLabels()
  File "D:\00 eigene Daten\000 FH\S 4\Regelungstechnik\Regelungsversuch\microRay\gui\plotWidget.py", line 347, in updateValueLabels
    xData, yData = firstCurve.getData()
AttributeError: 'NoneType' object has no attribute 'getData'

2018-02-17 14:38:02,198 ERROR    uncaught exception
2018-02-17 14:38:02,198 ERROR    
2018-02-17 14:38:02,280 CRITICAL uncaught exception:

Traceback (most recent call last):
  File "D:\00 eigene Daten\000 FH\S 4\Regelungstechnik\Regelungsversuch\microRay\gui\plotWidget.py", line 300, in updatePlots
    self.updateValueLabels()
  File "D:\00 eigene Daten\000 FH\S 4\Regelungstechnik\Regelungsversuch\microRay\gui\plotWidget.py", line 347, in updateValueLabels
    xData, yData = firstCurve.getData()
AttributeError: 'NoneType' object has no attribute 'getData'

2018-02-17 14:38:02,306 ERROR    uncaught exception
2018-02-17 14:38:02,306 ERROR    
2018-02-17 14:38:02,326 CRITICAL uncaught exception:

Traceback (most recent call last):
  File "D:\00 eigene Daten\000 FH\S 4\Regelungstechnik\Regelungsversuch\microRay\gui\plotWidget.py", line 300, in updatePlots
    self.updateValueLabels()
  File "D:\00 eigene Daten\000 FH\S 4\Regelungstechnik\Regelungsversuch\microRay\gui\plotWidget.py", line 347, in updateValueLabels
    xData, yData = firstCurve.getData()
AttributeError: 'NoneType' object has no attribute 'getData'

2018-02-17 14:38:02,352 ERROR    uncaught exception
2018-02-17 14:38:02,352 ERROR    
2018-02-17 14:38:02,375 CRITICAL uncaught exception:

Traceback (most recent call last):
  File "D:\00 eigene Daten\000 FH\S 4\Regelungstechnik\Regelungsversuch\microRay\gui\plotWidget.py", line 300, in updatePlots
    self.updateValueLabels()
  File "D:\00 eigene Daten\000 FH\S 4\Regelungstechnik\Regelungsversuch\microRay\gui\plotWidget.py", line 347, in updateValueLabels
    xData, yData = firstCurve.getData()
AttributeError: 'NoneType' object has no attribute 'getData'

2018-02-17 14:38:02,401 ERROR    uncaught exception
2018-02-17 14:38:02,401 ERROR    
2018-02-17 14:38:02,420 CRITICAL uncaught exception:

Traceback (most recent call last):
  File "D:\00 eigene Daten\000 FH\S 4\Regelungstechnik\Regelungsversuch\microRay\gui\plotWidget.py", line 300, in updatePlots
    self.updateValueLabels()
  File "D:\00 eigene Daten\000 FH\S 4\Regelungstechnik\Regelungsversuch\microRay\gui\plotWidget.py", line 347, in updateValueLabels
    xData, yData = firstCurve.getData()
AttributeError: 'NoneType' object has no attribute 'getData'

2018-02-17 14:38:02,446 ERROR    uncaught exception
2018-02-17 14:38:02,446 ERROR    
2018-02-17 14:38:02,473 CRITICAL uncaught exception:

Traceback (most recent call last):
  File "D:\00 eigene Daten\000 FH\S 4\Regelungstechnik\Regelungsversuch\microRay\gui\plotWidget.py", line 300, in updatePlots
    self.updateValueLabels()
  File "D:\00 eigene Daten\000 FH\S 4\Regelungstechnik\Regelungsversuch\microRay\gui\plotWidget.py", line 347, in updateValueLabels
    xData, yData = firstCurve.getData()
AttributeError: 'NoneType' object has no attribute 'getData'

2018-02-17 14:38:02,497 ERROR    uncaught exception
2018-02-17 14:38:02,497 ERROR    
2018-02-17 14:38:02,512 CRITICAL uncaught exception:

Traceback (most recent call last):
  File "D:\00 eigene Daten\000 FH\S 4\Regelungstechnik\Regelungsversuch\microRay\gui\plotWidget.py", line 300, in updatePlots
    self.updateValueLabels()
  File "D:\00 eigene Daten\000 FH\S 4\Regelungstechnik\Regelungsversuch\microRay\gui\plotWidget.py", line 347, in updateValueLabels
    xData, yData = firstCurve.getData()
AttributeError: 'NoneType' object has no attribute 'getData'

2018-02-17 14:38:02,538 ERROR    uncaught exception
2018-02-17 14:38:02,539 ERROR    
2018-02-17 14:38:02,563 CRITICAL uncaught exception:

Traceback (most recent call last):
  File "D:\00 eigene Daten\000 FH\S 4\Regelungstechnik\Regelungsversuch\microRay\gui\plotWidget.py", line 300, in updatePlots
    self.updateValueLabels()
  File "D:\00 eigene Daten\000 FH\S 4\Regelungstechnik\Regelungsversuch\microRay\gui\plotWidget.py", line 347, in updateValueLabels
    xData, yData = firstCurve.getData()
AttributeError: 'NoneType' object has no attribute 'getData'

2018-02-17 14:38:02,592 ERROR    uncaught exception
2018-02-17 14:38:02,592 ERROR    
2018-02-17 14:38:02,605 CRITICAL uncaught exception:

Traceback (most recent call last):
  File "D:\00 eigene Daten\000 FH\S 4\Regelungstechnik\Regelungsversuch\microRay\gui\plotWidget.py", line 300, in updatePlots
    self.updateValueLabels()
  File "D:\00 eigene Daten\000 FH\S 4\Regelungstechnik\Regelungsversuch\microRay\gui\plotWidget.py", line 347, in updateValueLabels
    xData, yData = firstCurve.getData()
AttributeError: 'NoneType' object has no attribute 'getData'

2018-02-17 14:38:02,632 ERROR    uncaught exception
2018-02-17 14:38:02,632 ERROR    
2018-02-17 14:38:02,654 CRITICAL uncaught exception:

Traceback (most recent call last):
  File "D:\00 eigene Daten\000 FH\S 4\Regelungstechnik\Regelungsversuch\microRay\gui\plotWidget.py", line 300, in updatePlots
    self.updateValueLabels()
  File "D:\00 eigene Daten\000 FH\S 4\Regelungstechnik\Regelungsversuch\microRay\gui\plotWidget.py", line 347, in updateValueLabels
    xData, yData = firstCurve.getData()
AttributeError: 'NoneType' object has no attribute 'getData'

2018-02-17 14:38:02,680 ERROR    uncaught exception
2018-02-17 14:38:02,680 ERROR    
2018-02-17 14:38:02,703 CRITICAL uncaught exception:

Traceback (most recent call last):
  File "D:\00 eigene Daten\000 FH\S 4\Regelungstechnik\Regelungsversuch\microRay\gui\plotWidget.py", line 300, in updatePlots
    self.updateValueLabels()
  File "D:\00 eigene Daten\000 FH\S 4\Regelungstechnik\Regelungsversuch\microRay\gui\plotWidget.py", line 347, in updateValueLabels
    xData, yData = firstCurve.getData()
AttributeError: 'NoneType' object has no attribute 'getData'

2018-02-17 14:38:02,734 ERROR    uncaught exception
2018-02-17 14:38:02,734 ERROR    
2018-02-17 14:38:02,753 CRITICAL uncaught exception:

Traceback (most recent call last):
  File "D:\00 eigene Daten\000 FH\S 4\Regelungstechnik\Regelungsversuch\microRay\gui\plotWidget.py", line 300, in updatePlots
    self.updateValueLabels()
  File "D:\00 eigene Daten\000 FH\S 4\Regelungstechnik\Regelungsversuch\microRay\gui\plotWidget.py", line 347, in updateValueLabels
    xData, yData = firstCurve.getData()
AttributeError: 'NoneType' object has no attribute 'getData'

2018-02-17 14:38:02,779 ERROR    uncaught exception
2018-02-17 14:38:02,779 ERROR    
2018-02-17 14:38:02,798 CRITICAL uncaught exception:

Traceback (most recent call last):
  File "D:\00 eigene Daten\000 FH\S 4\Regelungstechnik\Regelungsversuch\microRay\gui\plotWidget.py", line 300, in updatePlots
    self.updateValueLabels()
  File "D:\00 eigene Daten\000 FH\S 4\Regelungstechnik\Regelungsversuch\microRay\gui\plotWidget.py", line 347, in updateValueLabels
    xData, yData = firstCurve.getData()
AttributeError: 'NoneType' object has no attribute 'getData'

2018-02-17 14:38:02,822 ERROR    uncaught exception
2018-02-17 14:38:02,823 ERROR    
2018-02-17 14:38:02,842 CRITICAL uncaught exception:

Traceback (most recent call last):
  File "D:\00 eigene Daten\000 FH\S 4\Regelungstechnik\Regelungsversuch\microRay\gui\plotWidget.py", line 300, in updatePlots
    self.updateValueLabels()
  File "D:\00 eigene Daten\000 FH\S 4\Regelungstechnik\Regelungsversuch\microRay\gui\plotWidget.py", line 347, in updateValueLabels
    xData, yData = firstCurve.getData()
AttributeError: 'NoneType' object has no attribute 'getData'

2018-02-17 14:38:02,868 ERROR    uncaught exception
2018-02-17 14:38:02,868 ERROR    
2018-02-17 14:38:02,890 CRITICAL uncaught exception:

Traceback (most recent call last):
  File "D:\00 eigene Daten\000 FH\S 4\Regelungstechnik\Regelungsversuch\microRay\gui\plotWidget.py", line 300, in updatePlots
    self.updateValueLabels()
  File "D:\00 eigene Daten\000 FH\S 4\Regelungstechnik\Regelungsversuch\microRay\gui\plotWidget.py", line 347, in updateValueLabels
    xData, yData = firstCurve.getData()
AttributeError: 'NoneType' object has no attribute 'getData'

2018-02-17 14:38:02,914 ERROR    uncaught exception
2018-02-17 14:38:02,914 ERROR    
2018-02-17 14:38:02,934 CRITICAL uncaught exception:

Traceback (most recent call last):
  File "D:\00 eigene Daten\000 FH\S 4\Regelungstechnik\Regelungsversuch\microRay\gui\plotWidget.py", line 300, in updatePlots
    self.updateValueLabels()
  File "D:\00 eigene Daten\000 FH\S 4\Regelungstechnik\Regelungsversuch\microRay\gui\plotWidget.py", line 347, in updateValueLabels
    xData, yData = firstCurve.getData()
AttributeError: 'NoneType' object has no attribute 'getData'

2018-02-17 14:38:02,960 ERROR    uncaught exception
2018-02-17 14:38:02,960 ERROR    
2018-02-17 14:38:02,982 CRITICAL uncaught exception:

Traceback (most recent call last):
  File "D:\00 eigene Daten\000 FH\S 4\Regelungstechnik\Regelungsversuch\microRay\gui\plotWidget.py", line 300, in updatePlots
    self.updateValueLabels()
  File "D:\00 eigene Daten\000 FH\S 4\Regelungstechnik\Regelungsversuch\microRay\gui\plotWidget.py", line 347, in updateValueLabels
    xData, yData = firstCurve.getData()
AttributeError: 'NoneType' object has no attribute 'getData'

2018-02-17 14:38:03,007 ERROR    uncaught exception
2018-02-17 14:38:03,007 ERROR    
2018-02-17 14:38:03,029 CRITICAL uncaught exception:

Traceback (most recent call last):
  File "D:\00 eigene Daten\000 FH\S 4\Regelungstechnik\Regelungsversuch\microRay\gui\plotWidget.py", line 300, in updatePlots
    self.updateValueLabels()
  File "D:\00 eigene Daten\000 FH\S 4\Regelungstechnik\Regelungsversuch\microRay\gui\plotWidget.py", line 347, in updateValueLabels
    xData, yData = firstCurve.getData()
AttributeError: 'NoneType' object has no attribute 'getData'

2018-02-17 14:38:03,055 ERROR    uncaught exception
2018-02-17 14:38:03,055 ERROR    
2018-02-17 14:38:03,078 CRITICAL uncaught exception:

Traceback (most recent call last):
  File "D:\00 eigene Daten\000 FH\S 4\Regelungstechnik\Regelungsversuch\microRay\gui\plotWidget.py", line 300, in updatePlots
    self.updateValueLabels()
  File "D:\00 eigene Daten\000 FH\S 4\Regelungstechnik\Regelungsversuch\microRay\gui\plotWidget.py", line 347, in updateValueLabels
    xData, yData = firstCurve.getData()
AttributeError: 'NoneType' object has no attribute 'getData'

2018-02-17 14:38:03,102 ERROR    uncaught exception
2018-02-17 14:38:03,104 ERROR    
2018-02-17 14:38:03,127 CRITICAL uncaught exception:

Traceback (most recent call last):
  File "D:\00 eigene Daten\000 FH\S 4\Regelungstechnik\Regelungsversuch\microRay\gui\plotWidget.py", line 300, in updatePlots
    self.updateValueLabels()
  File "D:\00 eigene Daten\000 FH\S 4\Regelungstechnik\Regelungsversuch\microRay\gui\plotWidget.py", line 347, in updateValueLabels
    xData, yData = firstCurve.getData()
AttributeError: 'NoneType' object has no attribute 'getData'

2018-02-17 14:38:03,151 ERROR    uncaught exception
2018-02-17 14:38:03,151 ERROR    
2018-02-17 14:38:03,171 CRITICAL uncaught exception:

Traceback (most recent call last):
  File "D:\00 eigene Daten\000 FH\S 4\Regelungstechnik\Regelungsversuch\microRay\gui\plotWidget.py", line 300, in updatePlots
    self.updateValueLabels()
  File "D:\00 eigene Daten\000 FH\S 4\Regelungstechnik\Regelungsversuch\microRay\gui\plotWidget.py", line 347, in updateValueLabels
    xData, yData = firstCurve.getData()
AttributeError: 'NoneType' object has no attribute 'getData'

2018-02-17 14:38:03,197 ERROR    uncaught exception
2018-02-17 14:38:03,197 ERROR    
2018-02-17 14:38:03,214 CRITICAL uncaught exception:

Traceback (most recent call last):
  File "D:\00 eigene Daten\000 FH\S 4\Regelungstechnik\Regelungsversuch\microRay\gui\plotWidget.py", line 300, in updatePlots
    self.updateValueLabels()
  File "D:\00 eigene Daten\000 FH\S 4\Regelungstechnik\Regelungsversuch\microRay\gui\plotWidget.py", line 347, in updateValueLabels
    xData, yData = firstCurve.getData()
AttributeError: 'NoneType' object has no attribute 'getData'

2018-02-17 14:38:03,240 ERROR    uncaught exception
2018-02-17 14:38:03,240 ERROR    
2018-02-17 14:38:03,263 CRITICAL uncaught exception:

Traceback (most recent call last):
  File "D:\00 eigene Daten\000 FH\S 4\Regelungstechnik\Regelungsversuch\microRay\gui\plotWidget.py", line 300, in updatePlots
    self.updateValueLabels()
  File "D:\00 eigene Daten\000 FH\S 4\Regelungstechnik\Regelungsversuch\microRay\gui\plotWidget.py", line 347, in updateValueLabels
    xData, yData = firstCurve.getData()
AttributeError: 'NoneType' object has no attribute 'getData'

2018-02-17 14:38:03,289 ERROR    uncaught exception
2018-02-17 14:38:03,289 ERROR    
2018-02-17 14:38:03,311 CRITICAL uncaught exception:

Traceback (most recent call last):
  File "D:\00 eigene Daten\000 FH\S 4\Regelungstechnik\Regelungsversuch\microRay\gui\plotWidget.py", line 300, in updatePlots
    self.updateValueLabels()
  File "D:\00 eigene Daten\000 FH\S 4\Regelungstechnik\Regelungsversuch\microRay\gui\plotWidget.py", line 347, in updateValueLabels
    xData, yData = firstCurve.getData()
AttributeError: 'NoneType' object has no attribute 'getData'

2018-02-17 14:38:03,336 ERROR    uncaught exception
2018-02-17 14:38:03,336 ERROR    
2018-02-17 14:38:03,357 CRITICAL uncaught exception:

Traceback (most recent call last):
  File "D:\00 eigene Daten\000 FH\S 4\Regelungstechnik\Regelungsversuch\microRay\gui\plotWidget.py", line 300, in updatePlots
    self.updateValueLabels()
  File "D:\00 eigene Daten\000 FH\S 4\Regelungstechnik\Regelungsversuch\microRay\gui\plotWidget.py", line 347, in updateValueLabels
    xData, yData = firstCurve.getData()
AttributeError: 'NoneType' object has no attribute 'getData'

2018-02-17 14:38:03,382 ERROR    uncaught exception
2018-02-17 14:38:03,382 ERROR    
2018-02-17 14:38:03,405 CRITICAL uncaught exception:

Traceback (most recent call last):
  File "D:\00 eigene Daten\000 FH\S 4\Regelungstechnik\Regelungsversuch\microRay\gui\plotWidget.py", line 300, in updatePlots
    self.updateValueLabels()
  File "D:\00 eigene Daten\000 FH\S 4\Regelungstechnik\Regelungsversuch\microRay\gui\plotWidget.py", line 347, in updateValueLabels
    xData, yData = firstCurve.getData()
AttributeError: 'NoneType' object has no attribute 'getData'

2018-02-17 14:38:03,451 ERROR    uncaught exception
2018-02-17 14:38:03,451 ERROR    
2018-02-17 14:38:03,500 CRITICAL uncaught exception:

Traceback (most recent call last):
  File "D:\00 eigene Daten\000 FH\S 4\Regelungstechnik\Regelungsversuch\microRay\gui\plotWidget.py", line 300, in updatePlots
    self.updateValueLabels()
  File "D:\00 eigene Daten\000 FH\S 4\Regelungstechnik\Regelungsversuch\microRay\gui\plotWidget.py", line 347, in updateValueLabels
    xData, yData = firstCurve.getData()
AttributeError: 'NoneType' object has no attribute 'getData'

2018-02-17 14:38:03,526 ERROR    uncaught exception
2018-02-17 14:38:03,526 ERROR    
2018-02-17 14:38:03,548 CRITICAL uncaught exception:

Traceback (most recent call last):
  File "D:\00 eigene Daten\000 FH\S 4\Regelungstechnik\Regelungsversuch\microRay\gui\plotWidget.py", line 300, in updatePlots
    self.updateValueLabels()
  File "D:\00 eigene Daten\000 FH\S 4\Regelungstechnik\Regelungsversuch\microRay\gui\plotWidget.py", line 347, in updateValueLabels
    xData, yData = firstCurve.getData()
AttributeError: 'NoneType' object has no attribute 'getData'

2018-02-17 14:38:03,596 ERROR    uncaught exception
2018-02-17 14:38:03,598 ERROR    
2018-02-17 14:38:03,638 CRITICAL uncaught exception:

Traceback (most recent call last):
  File "D:\00 eigene Daten\000 FH\S 4\Regelungstechnik\Regelungsversuch\microRay\gui\plotWidget.py", line 300, in updatePlots
    self.updateValueLabels()
  File "D:\00 eigene Daten\000 FH\S 4\Regelungstechnik\Regelungsversuch\microRay\gui\plotWidget.py", line 347, in updateValueLabels
    xData, yData = firstCurve.getData()
AttributeError: 'NoneType' object has no attribute 'getData'

2018-02-17 14:38:03,664 ERROR    uncaught exception
2018-02-17 14:38:03,664 ERROR    
2018-02-17 14:38:03,686 CRITICAL uncaught exception:

Traceback (most recent call last):
  File "D:\00 eigene Daten\000 FH\S 4\Regelungstechnik\Regelungsversuch\microRay\gui\plotWidget.py", line 300, in updatePlots
    self.updateValueLabels()
  File "D:\00 eigene Daten\000 FH\S 4\Regelungstechnik\Regelungsversuch\microRay\gui\plotWidget.py", line 347, in updateValueLabels
    xData, yData = firstCurve.getData()
AttributeError: 'NoneType' object has no attribute 'getData'

2018-02-17 14:38:03,710 ERROR    uncaught exception
2018-02-17 14:38:03,711 ERROR    
2018-02-17 14:38:03,733 CRITICAL uncaught exception:

Traceback (most recent call last):
  File "D:\00 eigene Daten\000 FH\S 4\Regelungstechnik\Regelungsversuch\microRay\gui\plotWidget.py", line 300, in updatePlots
    self.updateValueLabels()
  File "D:\00 eigene Daten\000 FH\S 4\Regelungstechnik\Regelungsversuch\microRay\gui\plotWidget.py", line 347, in updateValueLabels
    xData, yData = firstCurve.getData()
AttributeError: 'NoneType' object has no attribute 'getData'

2018-02-17 14:38:03,759 ERROR    uncaught exception
2018-02-17 14:38:03,759 ERROR    
2018-02-17 14:38:03,783 CRITICAL uncaught exception:

Traceback (most recent call last):
  File "D:\00 eigene Daten\000 FH\S 4\Regelungstechnik\Regelungsversuch\microRay\gui\plotWidget.py", line 300, in updatePlots
    self.updateValueLabels()
  File "D:\00 eigene Daten\000 FH\S 4\Regelungstechnik\Regelungsversuch\microRay\gui\plotWidget.py", line 347, in updateValueLabels
    xData, yData = firstCurve.getData()
AttributeError: 'NoneType' object has no attribute 'getData'

2018-02-17 14:38:03,809 ERROR    uncaught exception
2018-02-17 14:38:03,809 ERROR    
2018-02-17 14:38:03,829 CRITICAL uncaught exception:

Traceback (most recent call last):
  File "D:\00 eigene Daten\000 FH\S 4\Regelungstechnik\Regelungsversuch\microRay\gui\plotWidget.py", line 300, in updatePlots
    self.updateValueLabels()
  File "D:\00 eigene Daten\000 FH\S 4\Regelungstechnik\Regelungsversuch\microRay\gui\plotWidget.py", line 347, in updateValueLabels
    xData, yData = firstCurve.getData()
AttributeError: 'NoneType' object has no attribute 'getData'

2018-02-17 14:38:03,855 ERROR    uncaught exception
2018-02-17 14:38:03,855 ERROR    
2018-02-17 16:33:48,267 INFO     starting application
2018-02-17 16:33:51,877 INFO     GUI load complete
2018-02-17 16:34:50,321 INFO     starting application
2018-02-17 16:34:51,709 INFO     GUI load complete
2018-02-17 16:35:15,459 INFO     starting application
2018-02-17 16:35:17,003 INFO     GUI load complete
2018-02-17 16:35:17,355 CRITICAL uncaught exception:

Traceback (most recent call last):
  File "D:\00 eigene Daten\000 FH\S 4\Regelungstechnik\Regelungsversuch\microRay\gui\plotWidget.py", line 158, in mouseMoved
    xPosition = self.plotWidget.vb.mapSceneToView(event[0]).x()
  File "D:\00 eigene Daten\000 FH\S 4\Regelungstechnik\Regelungsversuch\microRay\pyqtgraph\widgets\PlotWidget.py", line 79, in __getattr__
    raise NameError(attr)
NameError: vb

2018-02-17 16:35:17,361 ERROR    uncaught exception
2018-02-17 16:35:17,362 ERROR    
2018-02-17 17:15:12,845 INFO     starting application
2018-02-17 17:15:18,678 INFO     GUI load complete
2018-02-17 17:15:19,385 CRITICAL uncaught exception:

Traceback (most recent call last):
  File "D:\00 eigene Daten\000 FH\S 4\Regelungstechnik\Regelungsversuch\microRay\gui\plotWidget.py", line 158, in mouseMoved
    xPosition = self.plotWidget.vb.mapSceneToView(event[0]).x()
  File "D:\00 eigene Daten\000 FH\S 4\Regelungstechnik\Regelungsversuch\microRay\pyqtgraph\widgets\PlotWidget.py", line 79, in __getattr__
    raise NameError(attr)
NameError: vb

2018-02-17 17:15:19,390 ERROR    uncaught exception
2018-02-17 17:15:19,391 ERROR    
2018-02-17 17:15:19,424 CRITICAL uncaught exception:

Traceback (most recent call last):
  File "D:\00 eigene Daten\000 FH\S 4\Regelungstechnik\Regelungsversuch\microRay\gui\plotWidget.py", line 158, in mouseMoved
    xPosition = self.plotWidget.vb.mapSceneToView(event[0]).x()
  File "D:\00 eigene Daten\000 FH\S 4\Regelungstechnik\Regelungsversuch\microRay\pyqtgraph\widgets\PlotWidget.py", line 79, in __getattr__
    raise NameError(attr)
NameError: vb

2018-02-17 17:15:19,427 ERROR    uncaught exception
2018-02-17 17:15:19,427 ERROR    
2018-02-17 17:15:19,447 CRITICAL uncaught exception:

Traceback (most recent call last):
  File "D:\00 eigene Daten\000 FH\S 4\Regelungstechnik\Regelungsversuch\microRay\gui\plotWidget.py", line 158, in mouseMoved
    xPosition = self.plotWidget.vb.mapSceneToView(event[0]).x()
  File "D:\00 eigene Daten\000 FH\S 4\Regelungstechnik\Regelungsversuch\microRay\pyqtgraph\widgets\PlotWidget.py", line 79, in __getattr__
    raise NameError(attr)
NameError: vb

2018-02-17 17:15:19,450 ERROR    uncaught exception
2018-02-17 17:15:19,450 ERROR    
2018-02-17 17:15:19,467 CRITICAL uncaught exception:

Traceback (most recent call last):
  File "D:\00 eigene Daten\000 FH\S 4\Regelungstechnik\Regelungsversuch\microRay\gui\plotWidget.py", line 158, in mouseMoved
    xPosition = self.plotWidget.vb.mapSceneToView(event[0]).x()
  File "D:\00 eigene Daten\000 FH\S 4\Regelungstechnik\Regelungsversuch\microRay\pyqtgraph\widgets\PlotWidget.py", line 79, in __getattr__
    raise NameError(attr)
NameError: vb

2018-02-17 17:15:19,470 ERROR    uncaught exception
2018-02-17 17:15:19,470 ERROR    
2018-02-17 17:15:19,496 CRITICAL uncaught exception:

Traceback (most recent call last):
  File "D:\00 eigene Daten\000 FH\S 4\Regelungstechnik\Regelungsversuch\microRay\gui\plotWidget.py", line 158, in mouseMoved
    xPosition = self.plotWidget.vb.mapSceneToView(event[0]).x()
  File "D:\00 eigene Daten\000 FH\S 4\Regelungstechnik\Regelungsversuch\microRay\pyqtgraph\widgets\PlotWidget.py", line 79, in __getattr__
    raise NameError(attr)
NameError: vb

2018-02-17 17:15:19,500 ERROR    uncaught exception
2018-02-17 17:15:19,500 ERROR    
2018-02-17 17:15:19,519 CRITICAL uncaught exception:

Traceback (most recent call last):
  File "D:\00 eigene Daten\000 FH\S 4\Regelungstechnik\Regelungsversuch\microRay\gui\plotWidget.py", line 158, in mouseMoved
    xPosition = self.plotWidget.vb.mapSceneToView(event[0]).x()
  File "D:\00 eigene Daten\000 FH\S 4\Regelungstechnik\Regelungsversuch\microRay\pyqtgraph\widgets\PlotWidget.py", line 79, in __getattr__
    raise NameError(attr)
NameError: vb

2018-02-17 17:15:19,523 ERROR    uncaught exception
2018-02-17 17:15:19,523 ERROR    
2018-02-17 17:15:19,543 CRITICAL uncaught exception:

Traceback (most recent call last):
  File "D:\00 eigene Daten\000 FH\S 4\Regelungstechnik\Regelungsversuch\microRay\gui\plotWidget.py", line 158, in mouseMoved
    xPosition = self.plotWidget.vb.mapSceneToView(event[0]).x()
  File "D:\00 eigene Daten\000 FH\S 4\Regelungstechnik\Regelungsversuch\microRay\pyqtgraph\widgets\PlotWidget.py", line 79, in __getattr__
    raise NameError(attr)
NameError: vb

2018-02-17 17:15:19,546 ERROR    uncaught exception
2018-02-17 17:15:19,546 ERROR    
2018-02-17 17:15:19,563 CRITICAL uncaught exception:

Traceback (most recent call last):
  File "D:\00 eigene Daten\000 FH\S 4\Regelungstechnik\Regelungsversuch\microRay\gui\plotWidget.py", line 158, in mouseMoved
    xPosition = self.plotWidget.vb.mapSceneToView(event[0]).x()
  File "D:\00 eigene Daten\000 FH\S 4\Regelungstechnik\Regelungsversuch\microRay\pyqtgraph\widgets\PlotWidget.py", line 79, in __getattr__
    raise NameError(attr)
NameError: vb

2018-02-17 17:15:19,566 ERROR    uncaught exception
2018-02-17 17:15:19,568 ERROR    
2018-02-17 17:15:19,588 CRITICAL uncaught exception:

Traceback (most recent call last):
  File "D:\00 eigene Daten\000 FH\S 4\Regelungstechnik\Regelungsversuch\microRay\gui\plotWidget.py", line 158, in mouseMoved
    xPosition = self.plotWidget.vb.mapSceneToView(event[0]).x()
  File "D:\00 eigene Daten\000 FH\S 4\Regelungstechnik\Regelungsversuch\microRay\pyqtgraph\widgets\PlotWidget.py", line 79, in __getattr__
    raise NameError(attr)
NameError: vb

2018-02-17 17:15:19,589 ERROR    uncaught exception
2018-02-17 17:15:19,591 ERROR    
2018-02-17 17:15:21,138 CRITICAL uncaught exception:

Traceback (most recent call last):
  File "D:\00 eigene Daten\000 FH\S 4\Regelungstechnik\Regelungsversuch\microRay\gui\plotWidget.py", line 158, in mouseMoved
    xPosition = self.plotWidget.vb.mapSceneToView(event[0]).x()
  File "D:\00 eigene Daten\000 FH\S 4\Regelungstechnik\Regelungsversuch\microRay\pyqtgraph\widgets\PlotWidget.py", line 79, in __getattr__
    raise NameError(attr)
NameError: vb

2018-02-17 17:15:21,141 ERROR    uncaught exception
2018-02-17 17:15:21,142 ERROR    
2018-02-17 17:15:21,161 CRITICAL uncaught exception:

Traceback (most recent call last):
  File "D:\00 eigene Daten\000 FH\S 4\Regelungstechnik\Regelungsversuch\microRay\gui\plotWidget.py", line 158, in mouseMoved
    xPosition = self.plotWidget.vb.mapSceneToView(event[0]).x()
  File "D:\00 eigene Daten\000 FH\S 4\Regelungstechnik\Regelungsversuch\microRay\pyqtgraph\widgets\PlotWidget.py", line 79, in __getattr__
    raise NameError(attr)
NameError: vb

2018-02-17 17:15:21,165 ERROR    uncaught exception
2018-02-17 17:15:21,165 ERROR    
2018-02-17 17:15:21,196 CRITICAL uncaught exception:

Traceback (most recent call last):
  File "D:\00 eigene Daten\000 FH\S 4\Regelungstechnik\Regelungsversuch\microRay\gui\plotWidget.py", line 158, in mouseMoved
    xPosition = self.plotWidget.vb.mapSceneToView(event[0]).x()
  File "D:\00 eigene Daten\000 FH\S 4\Regelungstechnik\Regelungsversuch\microRay\pyqtgraph\widgets\PlotWidget.py", line 79, in __getattr__
    raise NameError(attr)
NameError: vb

2018-02-17 17:15:21,200 ERROR    uncaught exception
2018-02-17 17:15:21,200 ERROR    
2018-02-17 17:15:21,229 CRITICAL uncaught exception:

Traceback (most recent call last):
  File "D:\00 eigene Daten\000 FH\S 4\Regelungstechnik\Regelungsversuch\microRay\gui\plotWidget.py", line 158, in mouseMoved
    xPosition = self.plotWidget.vb.mapSceneToView(event[0]).x()
  File "D:\00 eigene Daten\000 FH\S 4\Regelungstechnik\Regelungsversuch\microRay\pyqtgraph\widgets\PlotWidget.py", line 79, in __getattr__
    raise NameError(attr)
NameError: vb

2018-02-17 17:15:21,232 ERROR    uncaught exception
2018-02-17 17:15:21,232 ERROR    
2018-02-17 17:15:21,249 CRITICAL uncaught exception:

Traceback (most recent call last):
  File "D:\00 eigene Daten\000 FH\S 4\Regelungstechnik\Regelungsversuch\microRay\gui\plotWidget.py", line 158, in mouseMoved
    xPosition = self.plotWidget.vb.mapSceneToView(event[0]).x()
  File "D:\00 eigene Daten\000 FH\S 4\Regelungstechnik\Regelungsversuch\microRay\pyqtgraph\widgets\PlotWidget.py", line 79, in __getattr__
    raise NameError(attr)
NameError: vb

2018-02-17 17:15:21,252 ERROR    uncaught exception
2018-02-17 17:15:21,252 ERROR    
2018-02-17 17:15:21,272 CRITICAL uncaught exception:

Traceback (most recent call last):
  File "D:\00 eigene Daten\000 FH\S 4\Regelungstechnik\Regelungsversuch\microRay\gui\plotWidget.py", line 158, in mouseMoved
    xPosition = self.plotWidget.vb.mapSceneToView(event[0]).x()
  File "D:\00 eigene Daten\000 FH\S 4\Regelungstechnik\Regelungsversuch\microRay\pyqtgraph\widgets\PlotWidget.py", line 79, in __getattr__
    raise NameError(attr)
NameError: vb

2018-02-17 17:15:21,276 ERROR    uncaught exception
2018-02-17 17:15:21,276 ERROR    
2018-02-17 17:15:21,293 CRITICAL uncaught exception:

Traceback (most recent call last):
  File "D:\00 eigene Daten\000 FH\S 4\Regelungstechnik\Regelungsversuch\microRay\gui\plotWidget.py", line 158, in mouseMoved
    xPosition = self.plotWidget.vb.mapSceneToView(event[0]).x()
  File "D:\00 eigene Daten\000 FH\S 4\Regelungstechnik\Regelungsversuch\microRay\pyqtgraph\widgets\PlotWidget.py", line 79, in __getattr__
    raise NameError(attr)
NameError: vb

2018-02-17 17:15:21,296 ERROR    uncaught exception
2018-02-17 17:15:21,296 ERROR    
2018-02-17 17:19:11,489 INFO     starting application
2018-02-17 17:19:12,661 INFO     GUI load complete
2018-02-17 17:19:13,296 CRITICAL uncaught exception:

Traceback (most recent call last):
  File "D:\00 eigene Daten\000 FH\S 4\Regelungstechnik\Regelungsversuch\microRay\gui\plotWidget.py", line 160, in mouseMoved
    xPosition = plotItem.vb.mapSceneToView(event[0]).x()
AttributeError: 'PlotDataItem' object has no attribute 'vb'

2018-02-17 17:19:13,299 ERROR    uncaught exception
2018-02-17 17:19:13,301 ERROR    
2018-02-17 17:19:13,338 CRITICAL uncaught exception:

Traceback (most recent call last):
  File "D:\00 eigene Daten\000 FH\S 4\Regelungstechnik\Regelungsversuch\microRay\gui\plotWidget.py", line 160, in mouseMoved
    xPosition = plotItem.vb.mapSceneToView(event[0]).x()
AttributeError: 'PlotDataItem' object has no attribute 'vb'

2018-02-17 17:19:13,342 ERROR    uncaught exception
2018-02-17 17:19:13,342 ERROR    
2018-02-17 17:19:13,359 CRITICAL uncaught exception:

Traceback (most recent call last):
  File "D:\00 eigene Daten\000 FH\S 4\Regelungstechnik\Regelungsversuch\microRay\gui\plotWidget.py", line 160, in mouseMoved
    xPosition = plotItem.vb.mapSceneToView(event[0]).x()
AttributeError: 'PlotDataItem' object has no attribute 'vb'

2018-02-17 17:19:13,361 ERROR    uncaught exception
2018-02-17 17:19:13,361 ERROR    
2018-02-17 17:19:13,381 CRITICAL uncaught exception:

Traceback (most recent call last):
  File "D:\00 eigene Daten\000 FH\S 4\Regelungstechnik\Regelungsversuch\microRay\gui\plotWidget.py", line 160, in mouseMoved
    xPosition = plotItem.vb.mapSceneToView(event[0]).x()
AttributeError: 'PlotDataItem' object has no attribute 'vb'

2018-02-17 17:19:13,384 ERROR    uncaught exception
2018-02-17 17:19:13,384 ERROR    
2018-02-17 17:19:13,401 CRITICAL uncaught exception:

Traceback (most recent call last):
  File "D:\00 eigene Daten\000 FH\S 4\Regelungstechnik\Regelungsversuch\microRay\gui\plotWidget.py", line 160, in mouseMoved
    xPosition = plotItem.vb.mapSceneToView(event[0]).x()
AttributeError: 'PlotDataItem' object has no attribute 'vb'

2018-02-17 17:19:13,405 ERROR    uncaught exception
2018-02-17 17:19:13,405 ERROR    
2018-02-17 17:19:13,430 CRITICAL uncaught exception:

Traceback (most recent call last):
  File "D:\00 eigene Daten\000 FH\S 4\Regelungstechnik\Regelungsversuch\microRay\gui\plotWidget.py", line 160, in mouseMoved
    xPosition = plotItem.vb.mapSceneToView(event[0]).x()
AttributeError: 'PlotDataItem' object has no attribute 'vb'

2018-02-17 17:19:13,431 ERROR    uncaught exception
2018-02-17 17:19:13,431 ERROR    
2018-02-17 17:19:13,450 CRITICAL uncaught exception:

Traceback (most recent call last):
  File "D:\00 eigene Daten\000 FH\S 4\Regelungstechnik\Regelungsversuch\microRay\gui\plotWidget.py", line 160, in mouseMoved
    xPosition = plotItem.vb.mapSceneToView(event[0]).x()
AttributeError: 'PlotDataItem' object has no attribute 'vb'

2018-02-17 17:19:13,453 ERROR    uncaught exception
2018-02-17 17:19:13,453 ERROR    
2018-02-17 17:19:13,473 CRITICAL uncaught exception:

Traceback (most recent call last):
  File "D:\00 eigene Daten\000 FH\S 4\Regelungstechnik\Regelungsversuch\microRay\gui\plotWidget.py", line 160, in mouseMoved
    xPosition = plotItem.vb.mapSceneToView(event[0]).x()
AttributeError: 'PlotDataItem' object has no attribute 'vb'

2018-02-17 17:19:13,476 ERROR    uncaught exception
2018-02-17 17:19:13,476 ERROR    
2018-02-17 17:19:18,029 CRITICAL uncaught exception:

Traceback (most recent call last):
  File "D:\00 eigene Daten\000 FH\S 4\Regelungstechnik\Regelungsversuch\microRay\gui\plotWidget.py", line 160, in mouseMoved
    xPosition = plotItem.vb.mapSceneToView(event[0]).x()
AttributeError: 'PlotDataItem' object has no attribute 'vb'

2018-02-17 17:19:18,032 ERROR    uncaught exception
2018-02-17 17:19:18,032 ERROR    
2018-02-17 17:19:18,055 CRITICAL uncaught exception:

Traceback (most recent call last):
  File "D:\00 eigene Daten\000 FH\S 4\Regelungstechnik\Regelungsversuch\microRay\gui\plotWidget.py", line 160, in mouseMoved
    xPosition = plotItem.vb.mapSceneToView(event[0]).x()
AttributeError: 'PlotDataItem' object has no attribute 'vb'

2018-02-17 17:19:18,058 ERROR    uncaught exception
2018-02-17 17:19:18,059 ERROR    
2018-02-17 17:19:18,078 CRITICAL uncaught exception:

Traceback (most recent call last):
  File "D:\00 eigene Daten\000 FH\S 4\Regelungstechnik\Regelungsversuch\microRay\gui\plotWidget.py", line 160, in mouseMoved
    xPosition = plotItem.vb.mapSceneToView(event[0]).x()
AttributeError: 'PlotDataItem' object has no attribute 'vb'

2018-02-17 17:19:18,081 ERROR    uncaught exception
2018-02-17 17:19:18,081 ERROR    
2018-02-17 17:19:18,098 CRITICAL uncaught exception:

Traceback (most recent call last):
  File "D:\00 eigene Daten\000 FH\S 4\Regelungstechnik\Regelungsversuch\microRay\gui\plotWidget.py", line 160, in mouseMoved
    xPosition = plotItem.vb.mapSceneToView(event[0]).x()
AttributeError: 'PlotDataItem' object has no attribute 'vb'

2018-02-17 17:19:18,101 ERROR    uncaught exception
2018-02-17 17:19:18,101 ERROR    
2018-02-17 17:19:18,125 CRITICAL uncaught exception:

Traceback (most recent call last):
  File "D:\00 eigene Daten\000 FH\S 4\Regelungstechnik\Regelungsversuch\microRay\gui\plotWidget.py", line 160, in mouseMoved
    xPosition = plotItem.vb.mapSceneToView(event[0]).x()
AttributeError: 'PlotDataItem' object has no attribute 'vb'

2018-02-17 17:19:18,128 ERROR    uncaught exception
2018-02-17 17:19:18,128 ERROR    
2018-02-17 17:21:33,522 INFO     starting application
2018-02-17 17:21:34,933 INFO     GUI load complete
2018-02-17 17:24:40,812 INFO     starting application
2018-02-17 17:24:42,165 INFO     GUI load complete
2018-02-17 17:25:37,375 INFO     starting application
2018-02-17 17:25:38,641 INFO     GUI load complete
2018-02-17 17:41:19,724 INFO     starting application
2018-02-17 17:41:21,266 INFO     GUI load complete
2018-02-17 17:41:29,790 CRITICAL uncaught exception:

Traceback (most recent call last):
  File "D:\00 eigene Daten\000 FH\S 4\Regelungstechnik\Regelungsversuch\microRay\gui\mainWindow.py", line 624, in openRecent
    self.loadProject(recentPath)
  File "D:\00 eigene Daten\000 FH\S 4\Regelungstechnik\Regelungsversuch\microRay\gui\mainWindow.py", line 644, in loadProject
    self.addTabs(self.projectSettings.tabSettingsDescriptions)
  File "D:\00 eigene Daten\000 FH\S 4\Regelungstechnik\Regelungsversuch\microRay\gui\mainWindow.py", line 301, in addTabs
    self.addOnlyOneWidget(tabs)
  File "D:\00 eigene Daten\000 FH\S 4\Regelungstechnik\Regelungsversuch\microRay\gui\mainWindow.py", line 420, in addOnlyOneWidget
    self.serialMonitor)
  File "D:\00 eigene Daten\000 FH\S 4\Regelungstechnik\Regelungsversuch\microRay\gui\tabSmallGenericView.py", line 45, in __init__
    self.plotter = PlotWidget(self.channels, self.applicationSettings, self.projectSettings)
  File "D:\00 eigene Daten\000 FH\S 4\Regelungstechnik\Regelungsversuch\microRay\gui\plotWidget.py", line 121, in __init__
    self.topHorizontalLayout.setMargin(0)
AttributeError: 'PlotWidget' object has no attribute 'topHorizontalLayout'

2018-02-17 17:41:29,792 ERROR    uncaught exception
2018-02-17 17:41:29,792 ERROR    
2018-02-17 17:42:01,325 CRITICAL uncaught exception:

Traceback (most recent call last):
  File "D:\00 eigene Daten\000 FH\S 4\Regelungstechnik\Regelungsversuch\microRay\gui\mainWindow.py", line 624, in openRecent
    self.loadProject(recentPath)
  File "D:\00 eigene Daten\000 FH\S 4\Regelungstechnik\Regelungsversuch\microRay\gui\mainWindow.py", line 644, in loadProject
    self.addTabs(self.projectSettings.tabSettingsDescriptions)
  File "D:\00 eigene Daten\000 FH\S 4\Regelungstechnik\Regelungsversuch\microRay\gui\mainWindow.py", line 301, in addTabs
    self.addOnlyOneWidget(tabs)
  File "D:\00 eigene Daten\000 FH\S 4\Regelungstechnik\Regelungsversuch\microRay\gui\mainWindow.py", line 420, in addOnlyOneWidget
    self.serialMonitor)
  File "D:\00 eigene Daten\000 FH\S 4\Regelungstechnik\Regelungsversuch\microRay\gui\tabSmallGenericView.py", line 45, in __init__
    self.plotter = PlotWidget(self.channels, self.applicationSettings, self.projectSettings)
  File "D:\00 eigene Daten\000 FH\S 4\Regelungstechnik\Regelungsversuch\microRay\gui\plotWidget.py", line 121, in __init__
    self.topHorizontalLayout.setMargin(0)
AttributeError: 'PlotWidget' object has no attribute 'topHorizontalLayout'

2018-02-17 17:42:01,325 ERROR    uncaught exception
2018-02-17 17:42:01,326 ERROR    
2018-02-17 17:42:54,589 INFO     starting application
2018-02-17 17:42:56,009 INFO     GUI load complete
2018-02-17 17:43:17,319 CRITICAL uncaught exception:

Traceback (most recent call last):
  File "D:\00 eigene Daten\000 FH\S 4\Regelungstechnik\Regelungsversuch\microRay\gui\mainWindow.py", line 624, in openRecent
    self.loadProject(recentPath)
  File "D:\00 eigene Daten\000 FH\S 4\Regelungstechnik\Regelungsversuch\microRay\gui\mainWindow.py", line 644, in loadProject
    self.addTabs(self.projectSettings.tabSettingsDescriptions)
  File "D:\00 eigene Daten\000 FH\S 4\Regelungstechnik\Regelungsversuch\microRay\gui\mainWindow.py", line 301, in addTabs
    self.addOnlyOneWidget(tabs)
  File "D:\00 eigene Daten\000 FH\S 4\Regelungstechnik\Regelungsversuch\microRay\gui\mainWindow.py", line 420, in addOnlyOneWidget
    self.serialMonitor)
  File "D:\00 eigene Daten\000 FH\S 4\Regelungstechnik\Regelungsversuch\microRay\gui\tabSmallGenericView.py", line 45, in __init__
    self.plotter = PlotWidget(self.channels, self.applicationSettings, self.projectSettings)
  File "D:\00 eigene Daten\000 FH\S 4\Regelungstechnik\Regelungsversuch\microRay\gui\plotWidget.py", line 130, in __init__
    self.topHorizontalLayout.addWidget(self.topVerticalLayoutRight)
TypeError: QBoxLayout.addWidget(QWidget, int stretch=0, Qt.Alignment alignment=0): argument 1 has unexpected type 'QVBoxLayout'

2018-02-17 17:43:17,321 ERROR    uncaught exception
2018-02-17 17:43:17,321 ERROR    
2018-02-17 17:45:17,772 INFO     starting application
2018-02-17 17:45:19,384 INFO     GUI load complete
2018-02-17 17:46:11,476 INFO     starting application
2018-02-17 17:46:13,993 INFO     GUI load complete
2018-02-17 17:46:56,385 INFO     starting application
2018-02-17 17:46:58,619 INFO     GUI load complete
2018-02-17 17:51:41,846 INFO     starting application
2018-02-17 17:51:44,227 INFO     GUI load complete
2018-02-17 17:52:15,237 INFO     starting application
2018-02-17 17:52:17,332 INFO     GUI load complete
2018-02-17 17:52:56,753 INFO     starting application
2018-02-17 17:52:59,125 INFO     GUI load complete
2018-02-17 17:53:12,141 INFO     starting application
2018-02-17 17:53:13,697 INFO     GUI load complete
2018-02-17 17:53:26,644 INFO     starting application
2018-02-17 17:53:28,944 INFO     GUI load complete
2018-02-17 17:56:14,594 INFO     starting application
2018-02-17 17:56:16,638 INFO     GUI load complete
2018-02-17 17:58:02,318 INFO     starting application
2018-02-17 17:58:04,970 INFO     GUI load complete
2018-02-19 13:12:06,542 INFO     starting application
2018-02-19 13:12:27,148 INFO     GUI load complete
2018-02-19 16:00:21,332 INFO     starting application
2018-02-19 16:00:22,107 INFO     GUI load complete
2018-02-19 16:05:25,384 INFO     starting application
2018-02-19 16:05:26,036 INFO     GUI load complete
2018-02-19 16:40:36,204 INFO     starting application
2018-02-19 16:40:46,782 INFO     GUI load complete
2018-02-19 19:39:30,551 INFO     starting application
2018-02-19 19:39:39,164 INFO     GUI load complete
2018-02-20 08:31:50,368 INFO     starting application
2018-02-20 08:31:59,497 INFO     GUI load complete
2018-02-20 09:42:54,030 INFO     starting application
2018-02-20 09:42:54,957 INFO     GUI load complete
2018-02-20 11:51:28,211 INFO     starting application
2018-02-20 11:51:32,887 INFO     GUI load complete
2018-02-20 21:13:05,257 INFO     starting application
2018-02-20 21:13:15,278 INFO     GUI load complete
2018-02-20 21:54:16,323 INFO     starting application
2018-02-20 21:54:26,371 INFO     GUI load complete
2018-02-20 22:34:49,299 INFO     starting application
2018-02-20 22:34:50,480 INFO     GUI load complete
2018-02-21 09:02:00,983 INFO     starting application
2018-02-21 09:02:06,351 INFO     GUI load complete
2018-02-21 13:19:30,536 INFO     starting application
2018-02-21 13:19:39,882 INFO     GUI load complete
2018-02-21 14:22:00,753 INFO     starting application
2018-02-21 14:22:05,278 INFO     GUI load complete
2018-02-22 12:00:07,496 INFO     starting application
2018-02-22 12:00:14,990 INFO     GUI load complete
2018-02-22 12:15:47,052 INFO     starting application
2018-02-22 12:15:47,759 INFO     GUI load complete
2018-02-22 12:50:42,187 INFO     starting application
2018-02-22 12:50:43,155 INFO     GUI load complete
2018-02-22 13:32:34,589 INFO     starting application
2018-02-22 13:32:35,232 INFO     GUI load complete
2018-02-22 13:38:54,407 INFO     starting application
2018-02-22 13:38:55,111 INFO     GUI load complete
2018-02-22 15:44:01,408 INFO     starting application
2018-02-22 15:44:02,157 INFO     GUI load complete
2018-02-22 15:50:39,117 INFO     starting application
2018-02-22 15:50:39,783 INFO     GUI load complete
2018-02-23 10:05:22,361 INFO     starting application
2018-02-23 10:05:32,029 INFO     GUI load complete
2018-02-23 15:29:02,073 INFO     starting application
2018-02-23 15:29:07,420 INFO     GUI load complete
2018-02-23 19:23:24,736 INFO     starting application
2018-02-23 19:23:30,017 INFO     GUI load complete
2018-02-23 20:56:45,385 INFO     starting application
2018-02-23 20:56:46,217 INFO     GUI load complete
2018-02-24 14:05:03,638 INFO     starting application
2018-02-24 14:05:10,233 INFO     GUI load complete
2018-02-25 10:57:53,884 INFO     starting application
2018-02-25 10:58:04,441 INFO     GUI load complete
2018-02-25 12:53:45,306 INFO     starting application
2018-02-25 12:53:46,236 INFO     GUI load complete
2018-02-25 14:15:04,012 INFO     starting application
2018-02-25 14:15:05,351 INFO     GUI load complete
2018-02-25 15:09:34,398 INFO     starting application
2018-02-25 15:09:35,632 INFO     GUI load complete
2018-02-26 12:49:26,730 INFO     starting application
2018-02-26 12:49:32,823 INFO     GUI load complete
2018-02-26 12:58:47,950 INFO     starting application
2018-02-26 12:58:48,819 INFO     GUI load complete
2018-02-26 13:46:32,503 INFO     starting application
2018-02-26 13:46:35,352 INFO     GUI load complete
2018-02-26 15:33:02,358 INFO     <class 'PyQt4.QtCore.QString'>
